Workbook

Sheet Monitor
A1: Long ETFs
A2: #VALUE! | I2: #VALUE! | Q2: #VALUE!
A3: Last Price | B3: Volume | C3: Average Volume | I3: Last Price | J3: Volume | K3: Average Volume | Q3: Last Price | R3: Volume | S3: Average Volume
A4: {=_FV(A2,"Price")} -> 17.67 | B4: {=_FV(A2,"Volume")} -> 4013078 | C4: ='BOIL & HNU'!F2 -> 10 days | D4: ='BOIL & HNU'!G2 -> 20 Days | E4: ='BOIL & HNU'!H2 -> 1 month | F4: ='BOIL & HNU'!I2 -> 3 months | G4: ='BOIL & HNU'!J2 -> 6 months | H4: ='BOIL & HNU'!K2 -> 1 year | I4: {=_FV(I2,"Price")} -> 13.23 | J4: {=_FV(I2,"Volume")} -> 331803 | K4: ='BOIL & HNU'!Z2 -> 10 days | L4: ='BOIL & HNU'!AA2 -> 20 Days | M4: ='BOIL & HNU'!AB2 -> 1 month | N4: ='BOIL & HNU'!AC2 -> 3 months | O4: ='BOIL & HNU'!AD2 -> 6 months | P4: ='BOIL & HNU'!AE2 -> 1 year | Q4: {=_FV(Q2,"Price")} -> 1.6918 | R4: {=_FV(Q2,"Volume")} -> 92898 | S4: ='3NGL & 3NGS'!F2 -> 10 Days | T4: ='3NGL & 3NGS'!G2 -> 20 Days | U4: ='3NGL & 3NGS'!H2 -> 1 month | V4: ='3NGL & 3NGS'!I2 -> 3 months | W4: ='3NGL & 3NGS'!J2 -> 6 months | X4: ='3NGL & 3NGS'!K2 -> 12 months
C5: ='BOIL & HNU'!F3 -> 16739657 | D5: ='BOIL & HNU'!G3 -> 14581698 | E5: ='BOIL & HNU'!H3 -> 13822368 | F5: ='BOIL & HNU'!I3 -> 12697801 | G5: ='BOIL & HNU'!J3 -> 9397136.3 | H5: ='BOIL & HNU'!K3 -> 6081848.9 | K5: ='BOIL & HNU'!Z3 -> 2913262.6 | L5: ='BOIL & HNU'!AA3 -> 2890699 | M5: ='BOIL & HNU'!AB3 -> 2743986.7 | N5: ='BOIL & HNU'!AC3 -> 2425096.3 | O5: ='BOIL & HNU'!AD3 -> 1872943.1 | P5: ='BOIL & HNU'!AE3 -> 1237155.4 | S5: ='3NGL & 3NGS'!F3 -> 536277.9 | T5: ='3NGL & 3NGS'!G3 -> 374621.05 | U5: ='3NGL & 3NGS'!H3 -> 348957.03 | V5: ='3NGL & 3NGS'!I3 -> 288221.66 | W5: ='3NGL & 3NGS'!J3 -> 199146.93 | X5: ='3NGL & 3NGS'!K3 -> 117639.96
A6: Maximum Volume Period | I6: Maximum Volume Period | Q6: Maximum Volume Period
A7: ='BOIL & HNU'!G26 -> 10 days | B7: ='BOIL & HNU'!H26 -> 20 days | C7: ='BOIL & HNU'!I26 -> 1 months | D7: ='BOIL & HNU'!J26 -> 2 months | E7: ='BOIL & HNU'!K26 -> 3 months | F7: ='BOIL & HNU'!L26 -> 6 months | G7: ='BOIL & HNU'!M26 -> 12 months | H7: ='BOIL & HNU'!N26 -> 24 months | I7: ='BOIL & HNU'!AA26 -> 10 days | J7: ='BOIL & HNU'!AB26 -> 20 days | K7: ='BOIL & HNU'!AC26 -> 1 months | L7: ='BOIL & HNU'!AD26 -> 2 months | M7: ='BOIL & HNU'!AE26 -> 3 months | N7: ='BOIL & HNU'!AF26 -> 6 months | O7: ='BOIL & HNU'!AG26 -> 12 months | P7: ='BOIL & HNU'!AH26 -> 24 Months | Q7: ='3NGL & 3NGS'!G27 -> 10 days | R7: ='3NGL & 3NGS'!H27 -> 20 days | S7: ='3NGL & 3NGS'!I27 -> 1 months | T7: ='3NGL & 3NGS'!J27 -> 2 months | U7: ='3NGL & 3NGS'!K27 -> 3 months | V7: ='3NGL & 3NGS'!L27 -> 6 months | W7: ='3NGL & 3NGS'!M27 -> 12 months | X7: ='3NGL & 3NGS'!N27 -> 24 Months
A8: ='BOIL & HNU'!G27 -> 46090 | B8: ='BOIL & HNU'!H27 -> 46090 | C8: ='BOIL & HNU'!I27 -> 46090 | D8: ='BOIL & HNU'!J27 -> 46042 | E8: ='BOIL & HNU'!K27 -> 46042 | F8: ='BOIL & HNU'!L27 -> 46042 | G8: ='BOIL & HNU'!M27 -> 46042 | H8: ='BOIL & HNU'!N27 -> 46042 | I8: ='BOIL & HNU'!AA27 -> 46090 | J8: ='BOIL & HNU'!AB27 -> 46084 | K8: ='BOIL & HNU'!AC27 -> 46084 | L8: ='BOIL & HNU'!AD27 -> 46041 | M8: ='BOIL & HNU'!AE27 -> 46041 | N8: ='BOIL & HNU'!AF27 -> 46041 | O8: ='BOIL & HNU'!AG27 -> 46041 | P8: ='BOIL & HNU'!AH27 -> 46041 | Q8: ='3NGL & 3NGS'!G28 -> 46090 | R8: ='3NGL & 3NGS'!H28 -> 46090 | S8: ='3NGL & 3NGS'!I28 -> 46090 | T8: ='3NGL & 3NGS'!J28 -> 46090 | U8: ='3NGL & 3NGS'!K28 -> 46031 | V8: ='3NGL & 3NGS'!L28 -> 46031 | W8: ='3NGL & 3NGS'!M28 -> 46031 | X8: ='3NGL & 3NGS'!N28 -> 46031
A9: ='BOIL & HNU'!G28 -> 23978727 | B9: ='BOIL & HNU'!H28 -> 23978727 | C9: ='BOIL & HNU'!I28 -> 23978727 | D9: ='BOIL & HNU'!J28 -> 33500140 | E9: ='BOIL & HNU'!K28 -> 33500140 | F9: ='BOIL & HNU'!L28 -> 33500140 | G9: ='BOIL & HNU'!M28 -> 33500140 | H9: ='BOIL & HNU'!N28 -> 33500140 | I9: ='BOIL & HNU'!AA28 -> 3688887 | J9: ='BOIL & HNU'!AB28 -> 3864988 | K9: ='BOIL & HNU'!AC28 -> 3864988 | L9: ='BOIL & HNU'!AD28 -> 6486726 | M9: ='BOIL & HNU'!AE28 -> 6486726 | N9: ='BOIL & HNU'!AF28 -> 6486726 | O9: ='BOIL & HNU'!AG28 -> 6486726 | P9: ='BOIL & HNU'!AH28 -> 6486726 | Q9: ='3NGL & 3NGS'!G29 -> 1148226 | R9: ='3NGL & 3NGS'!H29 -> 1148226 | S9: ='3NGL & 3NGS'!I29 -> 1148226 | T9: ='3NGL & 3NGS'!J29 -> 1148226 | U9: ='3NGL & 3NGS'!K29 -> 1464959 | V9: ='3NGL & 3NGS'!L29 -> 1464959 | W9: ='3NGL & 3NGS'!M29 -> 1464959 | X9: ='3NGL & 3NGS'!N29 -> 1464959
A10: ='BOIL & HNU'!G29 -> 18.4 | B10: ='BOIL & HNU'!H29 -> 18.4 | C10: ='BOIL & HNU'!I29 -> 18.4 | D10: ='BOIL & HNU'!J29 -> 22.44 | E10: ='BOIL & HNU'!K29 -> 22.44 | F10: ='BOIL & HNU'!L29 -> 22.44 | G10: ='BOIL & HNU'!M29 -> 22.44 | H10: ='BOIL & HNU'!N29 -> 22.44 | I10: ='BOIL & HNU'!AA29 -> 13.73 | J10: ='BOIL & HNU'!AB29 -> 13.78 | K10: ='BOIL & HNU'!AC29 -> 13.78 | L10: ='BOIL & HNU'!AD29 -> 14.44 | M10: ='BOIL & HNU'!AE29 -> 14.44 | N10: ='BOIL & HNU'!AF29 -> 14.44 | O10: ='BOIL & HNU'!AG29 -> 14.44 | P10: ='BOIL & HNU'!AH29 -> 14.44 | Q10: ='3NGL & 3NGS'!G30 -> 1.8728 | R10: ='3NGL & 3NGS'!H30 -> 1.8728 | S10: ='3NGL & 3NGS'!I30 -> 1.8728 | T10: ='3NGL & 3NGS'!J30 -> 1.8728 | U10: ='3NGL & 3NGS'!K30 -> 2.1335 | V10: ='3NGL & 3NGS'!L30 -> 2.1335 | W10: ='3NGL & 3NGS'!M30 -> 2.1335 | X10: ='3NGL & 3NGS'!N30 -> 2.1335
A11: Maximum Price Period | I11: Maximum Price Period | Q11: Maximum Price Period
A12: ='BOIL & HNU'!G33 -> 10 days | B12: ='BOIL & HNU'!H33 -> 20 days | C12: ='BOIL & HNU'!I33 -> 1 months | D12: ='BOIL & HNU'!J33 -> 2 months | E12: ='BOIL & HNU'!K33 -> 3 months | F12: ='BOIL & HNU'!L33 -> 6 months | G12: ='BOIL & HNU'!M33 -> 12 months | H12: ='BOIL & HNU'!N33 -> 24 months | I12: ='BOIL & HNU'!AA33 -> 10 days | J12: ='BOIL & HNU'!AB33 -> 20 days | K12: ='BOIL & HNU'!AC33 -> 1 months | L12: ='BOIL & HNU'!AD33 -> 2 months | M12: ='BOIL & HNU'!AE33 -> 3 months | N12: ='BOIL & HNU'!AF33 -> 6 months | O12: ='BOIL & HNU'!AG33 -> 12 months | P12: ='BOIL & HNU'!AH33 -> 24 Months | Q12: ='3NGL & 3NGS'!G34 -> 10 days | R12: ='3NGL & 3NGS'!H34 -> 20 days | S12: ='3NGL & 3NGS'!I34 -> 1 months | T12: ='3NGL & 3NGS'!J34 -> 2 months | U12: ='3NGL & 3NGS'!K34 -> 3 months | V12: ='3NGL & 3NGS'!L34 -> 6 months | W12: ='3NGL & 3NGS'!M34 -> 12 months | X12: ='3NGL & 3NGS'!N34 -> 24 Months
A13: ='BOIL & HNU'!G34 -> 46093 | B13: ='BOIL & HNU'!H34 -> 46093 | C13: ='BOIL & HNU'!I34 -> 46093 | D13: ='BOIL & HNU'!J34 -> 46052 | E13: ='BOIL & HNU'!K34 -> 46052 | F13: ='BOIL & HNU'!L34 -> 45996 | G13: ='BOIL & HNU'!M34 -> 45735 | H13: ='BOIL & HNU'!N34 -> 45454 | I13: ='BOIL & HNU'!AA34 -> 46093 | J13: ='BOIL & HNU'!AB34 -> 46093 | K13: ='BOIL & HNU'!AC34 -> 46093 | L13: ='BOIL & HNU'!AD34 -> 46052 | M13: ='BOIL & HNU'!AE34 -> 46052 | N13: ='BOIL & HNU'!AF34 -> 46052 | O13: ='BOIL & HNU'!AG34 -> 45735 | P13: ='BOIL & HNU'!AH34 -> 45454 | Q13: ='3NGL & 3NGS'!G35 -> 46093 | R13: ='3NGL & 3NGS'!H35 -> 46084 | S13: ='3NGL & 3NGS'!I35 -> 46084 | T13: ='3NGL & 3NGS'!J35 -> 46052 | U13: ='3NGL & 3NGS'!K35 -> 46052 | V13: ='3NGL & 3NGS'!L35 -> 45996 | W13: ='3NGL & 3NGS'!M35 -> 45735 | X13: ='3NGL & 3NGS'!N35 -> 45435
A14: ='BOIL & HNU'!G35 -> 11540327 | B14: ='BOIL & HNU'!H35 -> 11540327 | C14: ='BOIL & HNU'!I35 -> 11540327 | D14: ='BOIL & HNU'!J35 -> 18659908 | E14: ='BOIL & HNU'!K35 -> 18659908 | F14: ='BOIL & HNU'!L35 -> 16625164 | G14: ='BOIL & HNU'!M35 -> 1773345 | H14: ='BOIL & HNU'!N35 -> 1941279 | I14: ='BOIL & HNU'!AA35 -> 1558382 | J14: ='BOIL & HNU'!AB35 -> 1558382 | K14: ='BOIL & HNU'!AC35 -> 1558382 | L14: ='BOIL & HNU'!AD35 -> 2386268 | M14: ='BOIL & HNU'!AE35 -> 2386268 | N14: ='BOIL & HNU'!AF35 -> 2386268 | O14: ='BOIL & HNU'!AG35 -> 185694 | P14: ='BOIL & HNU'!AH35 -> 568873 | Q14: ='3NGL & 3NGS'!G36 -> 257366 | R14: ='3NGL & 3NGS'!H36 -> 672434 | S14: ='3NGL & 3NGS'!I36 -> 672434 | T14: ='3NGL & 3NGS'!J36 -> 174811 | U14: ='3NGL & 3NGS'!K36 -> 174811 | V14: ='3NGL & 3NGS'!L36 -> 228568 | W14: ='3NGL & 3NGS'!M36 -> 3669 | X14: ='3NGL & 3NGS'!N36 -> 24338
A15: ='BOIL & HNU'!G36 -> 20.3 | B15: ='BOIL & HNU'!H36 -> 20.3 | C15: ='BOIL & HNU'!I36 -> 20.3 | D15: ='BOIL & HNU'!J36 -> 40.67 | E15: ='BOIL & HNU'!K36 -> 40.67 | F15: ='BOIL & HNU'!L36 -> 43.62 | G15: ='BOIL & HNU'!M36 -> 92.37 | H15: ='BOIL & HNU'!N36 -> 118.3 | I15: ='BOIL & HNU'!AA36 -> 15.11 | J15: ='BOIL & HNU'!AB36 -> 15.11 | K15: ='BOIL & HNU'!AC36 -> 15.11 | L15: ='BOIL & HNU'!AD36 -> 30.26 | M15: ='BOIL & HNU'!AE36 -> 30.26 | N15: ='BOIL & HNU'!AF36 -> 30.26 | O15: ='BOIL & HNU'!AG36 -> 61.91 | P15: ='BOIL & HNU'!AH36 -> 78.48 | Q15: ='3NGL & 3NGS'!G37 -> 1.9398 | R15: ='3NGL & 3NGS'!H37 -> 1.9765 | S15: ='3NGL & 3NGS'!I37 -> 1.9765 | T15: ='3NGL & 3NGS'!J37 -> 5.56 | U15: ='3NGL & 3NGS'!K37 -> 5.56 | V15: ='3NGL & 3NGS'!L37 -> 9.772 | W15: ='3NGL & 3NGS'!M37 -> 34.349 | X15: ='3NGL & 3NGS'!N37 -> 70.14
A17: Short ETFs
A18: #VALUE! | I18: #VALUE! | Q18: #VALUE!
A19: Last Price | B19: Volume | C19: Average Volume | I19: Last Price | J19: Volume | K19: Average Volume | Q19: Last Price | R19: Volume | S19: Average Volume
A20: {=_FV(A18,"Price")} -> 20.435 | B20: {=_FV(A18,"Volume")} -> 1744432 | C20: ='KOLD & HND'!F2 -> 10 days | D20: ='KOLD & HND'!G2 -> 20 Days | E20: ='KOLD & HND'!H2 -> 1 month | F20: ='KOLD & HND'!I2 -> 3 months | G20: ='KOLD & HND'!J2 -> 6 months | H20: ='KOLD & HND'!K2 -> 1 year | I20: {=_FV(I18,"Price")} -> 4.03 | J20: {=_FV(I18,"Volume")} -> 527869 | K20: ='KOLD & HND'!Z2 -> 10 days | L20: ='KOLD & HND'!AA2 -> 20 Days | M20: ='KOLD & HND'!AB2 -> 1 month | N20: ='KOLD & HND'!AC2 -> 3 months | O20: ='KOLD & HND'!AD2 -> 6 months | P20: ='KOLD & HND'!AE2 -> 1 year | Q20: {=_FV(Q18,"Price")} -> 11.62 | R20: {=_FV(Q18,"Volume")} -> 21271 | S20: ='3NGL & 3NGS'!V2 -> 10 Days | T20: ='3NGL & 3NGS'!W2 -> 20 Days | U20: ='3NGL & 3NGS'!X2 -> 1 month | V20: ='3NGL & 3NGS'!Y2 -> 3 months | W20: ='3NGL & 3NGS'!Z2 -> 6 months | X20: ='3NGL & 3NGS'!AA2 -> 12 months
C21: ='KOLD & HND'!F3 -> 8604151.5 | D21: ='KOLD & HND'!G3 -> 7334077.5 | E21: ='KOLD & HND'!H3 -> 9799045.1 | F21: ='KOLD & HND'!I3 -> 9699254.5 | G21: ='KOLD & HND'!J3 -> 6875682.1 | H21: ='KOLD & HND'!K3 -> 6255991.5 | K21: ='KOLD & HND'!Z3 -> 5946551.3 | L21: ='KOLD & HND'!AA3 -> 5924091.9 | M21: ='KOLD & HND'!AB3 -> 7273293.3 | N21: ='KOLD & HND'!AC3 -> 6498564.5 | O21: ='KOLD & HND'!AD3 -> 4536059.6 | P21: ='KOLD & HND'!AE3 -> 3899596.4 | S21: ='3NGL & 3NGS'!V3 -> 50794.1 | T21: ='3NGL & 3NGS'!W3 -> 52200 | U21: ='3NGL & 3NGS'!X3 -> 59133.267 | V21: ='3NGL & 3NGS'!Y3 -> 71778.422 | W21: ='3NGL & 3NGS'!Z3 -> 51075.475 | X21: ='3NGL & 3NGS'!AA3 -> 38285.524
A22: Maximum Volume Period | I22: Maximum Volume Period | Q22: Maximum Volume Period
A23: ='KOLD & HND'!G26 -> 10 days | B23: ='KOLD & HND'!H26 -> 20 days | C23: ='KOLD & HND'!I26 -> 1 months | D23: ='KOLD & HND'!J26 -> 2 months | E23: ='KOLD & HND'!K26 -> 3 months | F23: ='KOLD & HND'!L26 -> 6 months | G23: ='KOLD & HND'!M26 -> 12 months | H23: ='KOLD & HND'!N26 -> 24 months | I23: ='KOLD & HND'!AA26 -> 10 days | J23: ='KOLD & HND'!AB26 -> 20 days | K23: ='KOLD & HND'!AC26 -> 1 months | L23: ='KOLD & HND'!AD26 -> 2 months | M23: ='KOLD & HND'!AE26 -> 3 months | N23: ='KOLD & HND'!AF26 -> 6 months | O23: ='KOLD & HND'!AG26 -> 12 months | P23: ='KOLD & HND'!AH26 -> 24 months | Q23: ='3NGL & 3NGS'!W27 -> 10 days | R23: ='3NGL & 3NGS'!X27 -> 20 days | S23: ='3NGL & 3NGS'!Y27 -> 1 months | T23: ='3NGL & 3NGS'!Z27 -> 2 months | U23: ='3NGL & 3NGS'!AA27 -> 3 months | V23: ='3NGL & 3NGS'!AB27 -> 6 months | W23: ='3NGL & 3NGS'!AC27 -> 12 months | X23: ='3NGL & 3NGS'!AD27 -> 24 Months
A24: ='KOLD & HND'!G27 -> 46090 | B24: ='KOLD & HND'!H27 -> 46087 | C24: ='KOLD & HND'!I27 -> 46087 | D24: ='KOLD & HND'!J27 -> 46052 | E24: ='KOLD & HND'!K27 -> 46052 | F24: ='KOLD & HND'!L27 -> 46052 | G24: ='KOLD & HND'!M27 -> 46052 | H24: ='KOLD & HND'!N27 -> 46052 | I24: ='KOLD & HND'!AA27 -> 46090 | J24: ='KOLD & HND'!AB27 -> 46087 | K24: ='KOLD & HND'!AC27 -> 46087 | L24: ='KOLD & HND'!AD27 -> 46055 | M24: ='KOLD & HND'!AE27 -> 46055 | N24: ='KOLD & HND'!AF27 -> 46055 | O24: ='KOLD & HND'!AG27 -> 46055 | P24: ='KOLD & HND'!AH27 -> 46055 | Q24: ='3NGL & 3NGS'!W28 -> 46090 | R24: ='3NGL & 3NGS'!X28 -> 46090 | S24: ='3NGL & 3NGS'!Y28 -> 46072 | T24: ='3NGL & 3NGS'!Z28 -> 46044 | U24: ='3NGL & 3NGS'!AA28 -> 46044 | V24: ='3NGL & 3NGS'!AB28 -> 46044 | W24: ='3NGL & 3NGS'!AC28 -> 46044 | X24: ='3NGL & 3NGS'!AD28 -> 46044
A25: ='KOLD & HND'!G28 -> 11636973 | B25: ='KOLD & HND'!H28 -> 14374391 | C25: ='KOLD & HND'!I28 -> 14374391 | D25: ='KOLD & HND'!J28 -> 54026562 | E25: ='KOLD & HND'!K28 -> 54026562 | F25: ='KOLD & HND'!L28 -> 54026562 | G25: ='KOLD & HND'!M28 -> 54026562 | H25: ='KOLD & HND'!N28 -> 54026562 | I25: ='KOLD & HND'!AA28 -> 8547131 | J25: ='KOLD & HND'!AB28 -> 10243791 | K25: ='KOLD & HND'!AC28 -> 10243791 | L25: ='KOLD & HND'!AD28 -> 26722821 | M25: ='KOLD & HND'!AE28 -> 26722821 | N25: ='KOLD & HND'!AF28 -> 26722821 | O25: ='KOLD & HND'!AG28 -> 26722821 | P25: ='KOLD & HND'!AH28 -> 26722821 | Q25: ='3NGL & 3NGS'!W29 -> 115929 | R25: ='3NGL & 3NGS'!X29 -> 115929 | S25: ='3NGL & 3NGS'!Y29 -> 161697 | T25: ='3NGL & 3NGS'!Z29 -> 506916 | U25: ='3NGL & 3NGS'!AA29 -> 506916 | V25: ='3NGL & 3NGS'!AB29 -> 506916 | W25: ='3NGL & 3NGS'!AC29 -> 506916 | X25: ='3NGL & 3NGS'!AD29 -> 506916
A26: ='KOLD & HND'!G29 -> 20.14 | B26: ='KOLD & HND'!H29 -> 18.75 | C26: ='KOLD & HND'!I29 -> 18.75 | D26: ='KOLD & HND'!J29 -> 13.58 | E26: ='KOLD & HND'!K29 -> 13.58 | F26: ='KOLD & HND'!L29 -> 13.58 | G26: ='KOLD & HND'!M29 -> 13.58 | H26: ='KOLD & HND'!N29 -> 13.58 | I26: ='KOLD & HND'!AA29 -> 4 | J26: ='KOLD & HND'!AB29 -> 3.72 | K26: ='KOLD & HND'!AC29 -> 3.72 | L26: ='KOLD & HND'!AD29 -> 4.08 | M26: ='KOLD & HND'!AE29 -> 4.08 | N26: ='KOLD & HND'!AF29 -> 4.08 | O26: ='KOLD & HND'!AG29 -> 4.08 | P26: ='KOLD & HND'!AH29 -> 4.08 | Q26: ='3NGL & 3NGS'!W30 -> 11.07 | R26: ='3NGL & 3NGS'!X30 -> 11.07 | S26: ='3NGL & 3NGS'!Y30 -> 13.71 | T26: ='3NGL & 3NGS'!Z30 -> 10.97 | U26: ='3NGL & 3NGS'!AA30 -> 10.97 | V26: ='3NGL & 3NGS'!AB30 -> 10.97 | W26: ='3NGL & 3NGS'!AC30 -> 10.97 | X26: ='3NGL & 3NGS'!AD30 -> 10.97
A27: Minimum Price Period | I27: Minimum Price Period | Q27: Minimum Price Period
A28: ='KOLD & HND'!G33 -> 10 days | B28: ='KOLD & HND'!H33 -> 20 days | C28: ='KOLD & HND'!I33 -> 1 months | D28: ='KOLD & HND'!J33 -> 2 months | E28: ='KOLD & HND'!K33 -> 3 months | F28: ='KOLD & HND'!L33 -> 6 months | G28: ='KOLD & HND'!M33 -> 12 months | H28: ='KOLD & HND'!N33 -> 24 months | I28: ='KOLD & HND'!AA33 -> 10 days | J28: ='KOLD & HND'!AB33 -> 20 days | K28: ='KOLD & HND'!AC33 -> 1 months | L28: ='KOLD & HND'!AD33 -> 2 months | M28: ='KOLD & HND'!AE33 -> 3 months | N28: ='KOLD & HND'!AF33 -> 6 months | O28: ='KOLD & HND'!AG33 -> 12 months | P28: ='KOLD & HND'!AH33 -> 24 months | Q28: ='3NGL & 3NGS'!W34 -> 10 days | R28: ='3NGL & 3NGS'!X34 -> 20 days | S28: ='3NGL & 3NGS'!Y34 -> 1 months | T28: ='3NGL & 3NGS'!Z34 -> 2 months | U28: ='3NGL & 3NGS'!AA34 -> 3 months | V28: ='3NGL & 3NGS'!AB34 -> 6 months | W28: ='3NGL & 3NGS'!AC34 -> 12 months | X28: ='3NGL & 3NGS'!AD34 -> 24 Months
A29: ='KOLD & HND'!G34 -> 46097 | B29: ='KOLD & HND'!H34 -> 46079 | C29: ='KOLD & HND'!I34 -> 46079 | D29: ='KOLD & HND'!J34 -> 46038 | E29: ='KOLD & HND'!K34 -> 46031 | F29: ='KOLD & HND'!L34 -> 46031 | G29: ='KOLD & HND'!M34 -> 46031 | H29: ='KOLD & HND'!N34 -> 45604 | I29: ='KOLD & HND'!AA34 -> 46097 | J29: ='KOLD & HND'!AB34 -> 46079 | K29: ='KOLD & HND'!AC34 -> 46079 | L29: ='KOLD & HND'!AD34 -> 46038 | M29: ='KOLD & HND'!AE34 -> 46031 | N29: ='KOLD & HND'!AF34 -> 45946 | O29: ='KOLD & HND'!AG34 -> 45891 | P29: ='KOLD & HND'!AH34 -> 45378 | Q29: ='3NGL & 3NGS'!W35 -> 46091 | R29: ='3NGL & 3NGS'!X35 -> 46079 | S29: ='3NGL & 3NGS'!Y35 -> 46079 | T29: ='3NGL & 3NGS'!Z35 -> 46038 | U29: ='3NGL & 3NGS'!AA35 -> 46037 | V29: ='3NGL & 3NGS'!AB35 -> 46037 | W29: ='3NGL & 3NGS'!AC35 -> 46037 | X29: ='3NGL & 3NGS'!AD35 -> 45509
A30: ='KOLD & HND'!G35 -> 7811737 | B30: ='KOLD & HND'!H35 -> 4166447 | C30: ='KOLD & HND'!I35 -> 4166447 | D30: ='KOLD & HND'!J35 -> 2813218 | E30: ='KOLD & HND'!K35 -> 5605190 | F30: ='KOLD & HND'!L35 -> 5605190 | G30: ='KOLD & HND'!M35 -> 5605190 | H30: ='KOLD & HND'!N35 -> 1274211 | I30: ='KOLD & HND'!AA35 -> 4230730 | J30: ='KOLD & HND'!AB35 -> 4700547 | K30: ='KOLD & HND'!AC35 -> 4700547 | L30: ='KOLD & HND'!AD35 -> 1598796 | M30: ='KOLD & HND'!AE35 -> 3179601 | N30: ='KOLD & HND'!AF35 -> 1655462 | O30: ='KOLD & HND'!AG35 -> 1655332 | P30: ='KOLD & HND'!AH35 -> 660604 | Q30: ='3NGL & 3NGS'!W36 -> 37422 | R30: ='3NGL & 3NGS'!X36 -> 44767 | S30: ='3NGL & 3NGS'!Y36 -> 44767 | T30: ='3NGL & 3NGS'!Z36 -> 50354 | U30: ='3NGL & 3NGS'!AA36 -> 20176 | V30: ='3NGL & 3NGS'!AB36 -> 20176 | W30: ='3NGL & 3NGS'!AC36 -> 20176 | X30: ='3NGL & 3NGS'!AD36 -> 981
A31: ='KOLD & HND'!G36 -> 20.39 | B31: ='KOLD & HND'!H36 -> 23.93 | C31: ='KOLD & HND'!I36 -> 23.93 | D31: ='KOLD & HND'!J36 -> 45.24 | E31: ='KOLD & HND'!K36 -> 49.39 | F31: ='KOLD & HND'!L36 -> 49.39 | G31: ='KOLD & HND'!M36 -> 49.39 | H31: ='KOLD & HND'!N36 -> 82.81 | I31: ='KOLD & HND'!AA36 -> 4.05 | J31: ='KOLD & HND'!AB36 -> 4.82 | K31: ='KOLD & HND'!AC36 -> 4.82 | L31: ='KOLD & HND'!AD36 -> 9.13 | M31: ='KOLD & HND'!AE36 -> 9.95 | N31: ='KOLD & HND'!AF36 -> 10.42 | O31: ='KOLD & HND'!AG36 -> 11.03 | P31: ='KOLD & HND'!AH36 -> 30.2675 | Q31: ='3NGL & 3NGS'!W37 -> 11.84 | R31: ='3NGL & 3NGS'!X37 -> 15.67 | S31: ='3NGL & 3NGS'!Y37 -> 15.67 | T31: ='3NGL & 3NGS'!Z37 -> 35.2 | U31: ='3NGL & 3NGS'!AA37 -> 35.26 | V31: ='3NGL & 3NGS'!AB37 -> 35.26 | W31: ='3NGL & 3NGS'!AC37 -> 35.26 | X31: ='3NGL & 3NGS'!AD37 -> 128.4561

Sheet BOIL & HNU
A1: #VALUE! | F1: Average Volume | M1: Volume Moving Average ( VMA ) | U1: #VALUE! | Z1: Average Volume | AG1: Volume Moving Average ( VMA ) | AR1: $ Value Traded BOIL | AU1: $ Value Traded HNU | BC1: {=_xlfn._xlws.FILTER(BA4000:BB6000, BA4000:BA6000<>"")} -> Filtered Date BOIL | BD1: Filtered Value BOIL | BF1: {=_xlfn._xlws.FILTER(BD4000:BE6000, BD4000:BD6000<>"")} -> Filtered Date HNU | BG1: Filtered Value HNU
A2: {=_xlfn.STOCKHISTORY(A1,DATE(2020,2,25),TODAY(),0,1,0,1,5)} -> Date | B2: Close | C2: Volume | D2: % Change | F2: 10 days | G2: 20 Days | H2: 1 month | I2: 3 months | J2: 6 months | K2: 1 year | M2: 10 Days | N2: 20 Days | O2: 50 Days | P2: 100 Days | Q2: 200 Days | R2: 360 Days | U2: {=_xlfn.STOCKHISTORY(U1,DATE(2020,2,25),TODAY(),0,1,0,1,5)} -> Date | V2: Close | W2: Volume | X2: % Change | Z2: 10 days | AA2: 20 Days | AB2: 1 month | AC2: 3 months | AD2: 6 months | AE2: 1 year | AG2: 10 Days | AH2: 20 Days | AI2: 50 Days | AJ2: 100 Days | AK2: 200 Days | AL2: 360 Days | AR2: Date | AS2: Value | AT2: % Vol Percentile | AU2: Date | AV2: Value | AW2: % Vol Percentile | AY2: #VALUE! | BC2: 45831 | BD2: 2.4482988e+08 | BF2: 45875 | BG2: 19775717 | BI2: =_xlfn.PERCENTILE.INC(AS:AS, 0.9) -> 3.0616278e+08 | BJ2: =_xlfn.PERCENTILE.INC(C:C, 0.9) -> 5166631.7 | BK2: =MAX(C:C) -> 33500140 | BM2: =_xlfn.PERCENTILE.INC(AV3:AV5000, 0.9) -> 41167141 | BN2: =_xlfn.PERCENTILE.INC(W3:W5000, 0.9) -> 1127455.4 | BO2: =MAX(W3:W5000) -> 6486726
A3: 43886 | B3: 5755 | C3: 263 | D3: - | F3: =AVERAGE(_xlfn.TAKE(INDEX(_xlfn.ANCHORARRAY(A2), , 3), -10)) -> 16739657 | G3: =AVERAGE(_xlfn.TAKE(INDEX(_xlfn.ANCHORARRAY(A2), , 3), -20)) -> 14581698 | H3: =AVERAGE(_xlfn.TAKE(INDEX(_xlfn.ANCHORARRAY(A2), , 3), -30)) -> 13822368 | I3: =AVERAGE(_xlfn.TAKE(INDEX(_xlfn.ANCHORARRAY(A2), , 3), -90)) -> 12697801 | J3: =AVERAGE(_xlfn.TAKE(INDEX(_xlfn.ANCHORARRAY(A2), , 3), -180)) -> 9397136.3 | K3: =AVERAGE(_xlfn.TAKE(INDEX(_xlfn.ANCHORARRAY(A2), , 3), -365)) -> 6081848.9 | M3: {=_xlfn.LET( _xlpm.Last10, _xlfn.TAKE(_xlfn.ANCHORARRAY(A2), -10), _xlpm.Price, INDEX(_xlpm.Last10, , 2), _xlpm.Vol, INDEX(_xlpm.Last10, , 3), SUM(_xlpm.Price * _xlpm.Vol) / SUM(_xlpm.Vol) )} -> 18.625594 | N3: {=_xlfn.LET( _xlpm.Last20, _xlfn.TAKE(_xlfn.ANCHORARRAY(A2), -20), _xlpm.Price, INDEX(_xlpm.Last20, , 2), _xlpm.Vol, INDEX(_xlpm.Last20, , 3), SUM(_xlpm.Price * _xlpm.Vol) / SUM(_xlpm.Vol) )} -> 17.973472 | O3: {=_xlfn.LET( _xlpm.Last50, _xlfn.TAKE(_xlfn.ANCHORARRAY(A2), -50), _xlpm.Price, INDEX(_xlpm.Last50, , 2), _xlpm.Vol, INDEX(_xlpm.Last50, , 3), SUM(_xlpm.Price * _xlpm.Vol) / SUM(_xlpm.Vol) )} -> 21.470415 | P3: {=_xlfn.LET( _xlpm.Last100, _xlfn.TAKE(_xlfn.ANCHORARRAY(A2), -100), _xlpm.Price, INDEX(_xlpm.Last100, , 2), _xlpm.Vol, INDEX(_xlpm.Last100, , 3), SUM(_xlpm.Price * _xlpm.Vol) / SUM(_xlpm.Vol) )} -> 24.81456 | Q3: {=_xlfn.LET( _xlpm.Last200, _xlfn.TAKE(_xlfn.ANCHORARRAY(A2), -200), _xlpm.Price, INDEX(_xlpm.Last200, , 2), _xlpm.Vol, INDEX(_xlpm.Last200, , 3), SUM(_xlpm.Price * _xlpm.Vol) / SUM(_xlpm.Vol) )} -> 27.842094 | R3: {=_xlfn.LET( _xlpm.Last360, _xlfn.TAKE(_xlfn.ANCHORARRAY(A2), -360), _xlpm.Price, INDEX(_xlpm.Last360, , 2), _xlpm.Vol, INDEX(_xlpm.Last360, , 3), SUM(_xlpm.Price * _xlpm.Vol) / SUM(_xlpm.Vol) )} -> 33.781119 | U3: 43886 | V3: 3843 | W3: 2142 | X3: - | Z3: =AVERAGE(_xlfn.TAKE(INDEX(_xlfn.ANCHORARRAY(U2), , 3), -10)) -> 2913262.6 | AA3: =AVERAGE(_xlfn.TAKE(INDEX(_xlfn.ANCHORARRAY(U2), , 3), -20)) -> 2890699 | AB3: =AVERAGE(_xlfn.TAKE(INDEX(_xlfn.ANCHORARRAY(U2), , 3), -30)) -> 2743986.7 | AC3: =AVERAGE(_xlfn.TAKE(INDEX(_xlfn.ANCHORARRAY(U2), , 3), -90)) -> 2425096.3 | AD3: =AVERAGE(_xlfn.TAKE(INDEX(_xlfn.ANCHORARRAY(U2), , 3), -180)) -> 1872943.1 | AE3: =AVERAGE(_xlfn.TAKE(INDEX(_xlfn.ANCHORARRAY(U2), , 3), -365)) -> 1237155.4 | AG3: {=_xlfn.LET( _xlpm.Last10, _xlfn.TAKE(_xlfn.ANCHORARRAY(U2), -10), _xlpm.Price, INDEX(_xlpm.Last10, , 2), _xlpm.Vol, INDEX(_xlpm.Last10, , 3), SUM(_xlpm.Price * _xlpm.Vol) / SUM(_xlpm.Vol) )} -> 13.882622 | AH3: {=_xlfn.LET( _xlpm.Last20, _xlfn.TAKE(_xlfn.ANCHORARRAY(U2), -20), _xlpm.Price, INDEX(_xlpm.Last20, , 2), _xlpm.Vol, INDEX(_xlpm.Last20, , 3), SUM(_xlpm.Price * _xlpm.Vol) / SUM(_xlpm.Vol) )} -> 13.286541 | AI3: {=_xlfn.LET( _xlpm.Last50, _xlfn.TAKE(_xlfn.ANCHORARRAY(U2), -50), _xlpm.Price, INDEX(_xlpm.Last50, , 2), _xlpm.Vol, INDEX(_xlpm.Last50, , 3), SUM(_xlpm.Price * _xlpm.Vol) / SUM(_xlpm.Vol) )} -> 15.13651 | AJ3: {=_xlfn.LET( _xlpm.Last100, _xlfn.TAKE(_xlfn.ANCHORARRAY(U2), -100), _xlpm.Price, INDEX(_xlpm.Last100, , 2), _xlpm.Vol, INDEX(_xlpm.Last100, , 3), SUM(_xlpm.Price * _xlpm.Vol) / SUM(_xlpm.Vol) )} -> 16.783311 | AK3: {=_xlfn.LET( _xlpm.Last200, _xlfn.TAKE(_xlfn.ANCHORARRAY(U2), -200), _xlpm.Price, INDEX(_xlpm.Last200, , 2), _xlpm.Vol, INDEX(_xlpm.Last200, , 3), SUM(_xlpm.Price * _xlpm.Vol) / SUM(_xlpm.Vol) )} -> 18.49625 | AL3: {=_xlfn.LET( _xlpm.Last360, _xlfn.TAKE(_xlfn.ANCHORARRAY(U2), -360), _xlpm.Price, INDEX(_xlpm.Last360, , 2), _xlpm.Vol, INDEX(_xlpm.Last360, , 3), SUM(_xlpm.Price * _xlpm.Vol) / SUM(_xlpm.Vol) )} -> 22.246634 | AR3: =A3 -> 43886 | AS3: =B3*C3 -> 1513565 | AT3: =IF(AND($AS3 >= $BI$2, $C3 >= $BJ$2), ($C3 / $BK$2) * 100, "") | AU3: =U3 -> 43886 | AV3: =V3*W3 -> 8231706 | AW3: =IF(AND($AV3 >= $BM$2, $W3 >= $BN$2), ($W3 / $BO$2) * 100, "") | AY3: =IF(AND($AS3 >= $BI$2, $C3 >= $BJ$2), ($C3 / $BK$2) * 100, "") | BC3: 45832 | BD3: 1.6696233e+08 | BF3: 45876 | BG3: 25067601
A4: 43887 | B4: 5590 | C4: 259 | D4: =(B4-B3)/B3 -> -0.028670721 | U4: 43887 | V4: 3739.5 | W4: 2197 | X4: =(V4-V3)/V3 -> -0.026932084 | AR4: =A4 -> 43887 | AS4: =B4*C4 -> 1447810 | AT4: =IF(AND($AS4 >= $BI$2, $C4 >= $BJ$2), ($C4 / $BK$2) * 100, "") | AU4: =U4 -> 43887 | AV4: =V4*W4 -> 8215681.5 | AW4: =IF(AND($AV4 >= $BM$2, $W4 >= $BN$2), ($W4 / $BO$2) * 100, "") | BC4: 45833 | BD4: 1.4469777e+08 | BF4: 45877 | BG4: 32115861
A5: 43888 | B5: 5130 | C5: 636 | D5: =(B5-B4)/B4 -> -0.082289803 | U5: 43888 | V5: 3361.5 | W5: 3054 | X5: =(V5-V4)/V4 -> -0.10108303 | AR5: =A5 -> 43888 | AS5: =B5*C5 -> 3262680 | AT5: =IF(AND($AS5 >= $BI$2, $C5 >= $BJ$2), ($C5 / $BK$2) * 100, "") | AU5: =U5 -> 43888 | AV5: =V5*W5 -> 10266021 | AW5: =IF(AND($AV5 >= $BM$2, $W5 >= $BN$2), ($W5 / $BO$2) * 100, "") | BC5: 45834 | BD5: 253645076 | BF5: 45880 | BG5: 21788514
A6: 43889 | B6: 4830 | C6: 398 | D6: =(B6-B5)/B5 -> -0.058479532 | U6: 43889 | V6: 3204 | W6: 2949 | X6: =(V6-V5)/V5 -> -0.046854083 | AR6: =A6 -> 43889 | AS6: =B6*C6 -> 1922340 | AT6: =IF(AND($AS6 >= $BI$2, $C6 >= $BJ$2), ($C6 / $BK$2) * 100, "") | AU6: =U6 -> 43889 | AV6: =V6*W6 -> 9448596 | AW6: =IF(AND($AV6 >= $BM$2, $W6 >= $BN$2), ($W6 / $BO$2) * 100, "") | BC6: 45835 | BD6: 2.0952453e+08 | BF6: 45881 | BG6: 39833700
A7: 43892 | B7: 5130 | C7: 281 | D7: =(B7-B6)/B6 -> 0.062111801 | U7: 43892 | V7: 3438 | W7: 2792 | X7: =(V7-V6)/V6 -> 0.073033708 | AR7: =A7 -> 43892 | AS7: =B7*C7 -> 1441530 | AT7: =IF(AND($AS7 >= $BI$2, $C7 >= $BJ$2), ($C7 / $BK$2) * 100, "") | AU7: =U7 -> 43892 | AV7: =V7*W7 -> 9598896 | AW7: =IF(AND($AV7 >= $BM$2, $W7 >= $BN$2), ($W7 / $BO$2) * 100, "") | BC7: 45838 | BD7: 2.9927177e+08 | BF7: 45882 | BG7: 21971626
A8: 43893 | B8: 5400 | C8: 511 | D8: =(B8-B7)/B7 -> 0.052631579 | U8: 43893 | V8: 3618 | W8: 3443 | X8: =(V8-V7)/V7 -> 0.052356021 | AR8: =A8 -> 43893 | AS8: =B8*C8 -> 2759400 | AT8: =IF(AND($AS8 >= $BI$2, $C8 >= $BJ$2), ($C8 / $BK$2) * 100, "") | AU8: =U8 -> 43893 | AV8: =V8*W8 -> 12456774 | AW8: =IF(AND($AV8 >= $BM$2, $W8 >= $BN$2), ($W8 / $BO$2) * 100, "") | BC8: 45839 | BD8: 2.2775447e+08 | BF8: 45883 | BG8: 18852111
A9: 43894 | B9: 5595 | C9: 210 | D9: =(B9-B8)/B8 -> 0.036111111 | U9: 43894 | V9: 3753 | W9: 1870 | X9: =(V9-V8)/V8 -> 0.037313433 | AR9: =A9 -> 43894 | AS9: =B9*C9 -> 1174950 | AT9: =IF(AND($AS9 >= $BI$2, $C9 >= $BJ$2), ($C9 / $BK$2) * 100, "") | AU9: =U9 -> 43894 | AV9: =V9*W9 -> 7018110 | AW9: =IF(AND($AV9 >= $BM$2, $W9 >= $BN$2), ($W9 / $BO$2) * 100, "") | BC9: 45840 | BD9: 1.7521348e+08 | BF9: 45884 | BG9: 24139251
A10: 43895 | B10: 5190.1 | C10: 274 | D10: =(B10-B9)/B9 -> -0.072368186 | U10: 43895 | V10: 3465 | W10: 2943 | X10: =(V10-V9)/V9 -> -0.076738609 | AR10: =A10 -> 43895 | AS10: =B10*C10 -> 1422087.4 | AT10: =IF(AND($AS10 >= $BI$2, $C10 >= $BJ$2), ($C10 / $BK$2) * 100, "") | AU10: =U10 -> 43895 | AV10: =V10*W10 -> 10197495 | AW10: =IF(AND($AV10 >= $BM$2, $W10 >= $BN$2), ($W10 / $BO$2) * 100, "") | BC10: 45841 | BD10: 1.5698411e+08 | BF10: 45887 | BG10: 8539847
A11: 43896 | B11: 4950 | C11: 330 | D11: =(B11-B10)/B10 -> -0.046261151 | U11: 43896 | V11: 3312 | W11: 2467 | X11: =(V11-V10)/V10 -> -0.044155844 | AR11: =A11 -> 43896 | AS11: =B11*C11 -> 1633500 | AT11: =IF(AND($AS11 >= $BI$2, $C11 >= $BJ$2), ($C11 / $BK$2) * 100, "") | AU11: =U11 -> 43896 | AV11: =V11*W11 -> 8170704 | AW11: =IF(AND($AV11 >= $BM$2, $W11 >= $BN$2), ($W11 / $BO$2) * 100, "") | BC11: 45845 | BD11: 1.7868987e+08 | BF11: 45888 | BG11: 40162089
A12: 43899 | B12: 5520 | C12: 604 | D12: =(B12-B11)/B11 -> 0.11515152 | U12: 43899 | V12: 3690 | W12: 3877 | X12: =(V12-V11)/V11 -> 0.11413043 | AR12: =A12 -> 43899 | AS12: =B12*C12 -> 3334080 | AT12: =IF(AND($AS12 >= $BI$2, $C12 >= $BJ$2), ($C12 / $BK$2) * 100, "") | AU12: =U12 -> 43899 | AV12: =V12*W12 -> 14306130 | AW12: =IF(AND($AV12 >= $BM$2, $W12 >= $BN$2), ($W12 / $BO$2) * 100, "") | BC12: 45846 | BD12: 1.6199803e+08 | BF12: 45889 | BG12: 19773065
A13: 43900 | B13: 6180 | C13: 662 | D13: =(B13-B12)/B12 -> 0.11956522 | U13: 43900 | V13: 4131 | W13: 4603 | X13: =(V13-V12)/V12 -> 0.1195122 | AR13: =A13 -> 43900 | AS13: =B13*C13 -> 4091160 | AT13: =IF(AND($AS13 >= $BI$2, $C13 >= $BJ$2), ($C13 / $BK$2) * 100, "") | AU13: =U13 -> 43900 | AV13: =V13*W13 -> 19014993 | AW13: =IF(AND($AV13 >= $BM$2, $W13 >= $BN$2), ($W13 / $BO$2) * 100, "") | BC13: 45847 | BD13: 3.0170469e+08 | BF13: 45890 | BG13: 20741818
A14: 43901 | B14: 5830 | C14: 579 | D14: =(B14-B13)/B13 -> -0.056634304 | U14: 43901 | V14: 3888 | W14: 4694 | X14: =(V14-V13)/V13 -> -0.058823529 | AR14: =A14 -> 43901 | AS14: =B14*C14 -> 3375570 | AT14: =IF(AND($AS14 >= $BI$2, $C14 >= $BJ$2), ($C14 / $BK$2) * 100, "") | AU14: =U14 -> 43901 | AV14: =V14*W14 -> 18250272 | AW14: =IF(AND($AV14 >= $BM$2, $W14 >= $BN$2), ($W14 / $BO$2) * 100, "") | BC14: 45848 | BD14: 2.0638524e+08 | BF14: 45891 | BG14: 35941211
A15: 43902 | B15: 5550 | C15: 574 | D15: =(B15-B14)/B14 -> -0.048027444 | U15: 43902 | V15: 3717 | W15: 2858 | X15: =(V15-V14)/V14 -> -0.043981481 | AR15: =A15 -> 43902 | AS15: =B15*C15 -> 3185700 | AT15: =IF(AND($AS15 >= $BI$2, $C15 >= $BJ$2), ($C15 / $BK$2) * 100, "") | AU15: =U15 -> 43902 | AV15: =V15*W15 -> 10623186 | AW15: =IF(AND($AV15 >= $BM$2, $W15 >= $BN$2), ($W15 / $BO$2) * 100, "") | BC15: 45849 | BD15: 1.6775976e+08 | BF15: 45894 | BG15: 12513761
... A21: 43910 | B21: 4250 | C21: 282 | D21: =(B21-B20)/B20 -> -0.086021505 | U21: 43910 | V21: 2835 | W21: 2986 | X21: =(V21-V20)/V20 -> -0.081632653 | AR21: =A21 -> 43910 | AS21: =B21*C21 -> 1198500 | AT21: =IF(AND($AS21 >= $BI$2, $C21 >= $BJ$2), ($C21 / $BK$2) * 100, "") | AU21: =U21 -> 43910 | AV21: =V21*W21 -> 8465310 | AW21: =IF(AND($AV21 >= $BM$2, $W21 >= $BN$2), ($W21 / $BO$2) * 100, "") | BC21: 45859 | BD21: 2.5951123e+08 | BF21: 45903 | BG21: 16138987
A22: 43913 | B22: 4326.5 | C22: 367 | D22: =(B22-B21)/B21 -> 0.018 | G22: Last Price | H22: Volume | I22: Change | J22: 52 Week High | K22: 52 Week Low | P22: Period | Q22: Date Range | U22: 43913 | V22: 2889 | W22: 2516 | X22: =(V22-V21)/V21 -> 0.019047619 | AA22: Last Price | AB22: Volume | AC22: Change | AD22: 52 Week High | AE22: 52 Week Low | AJ22: Period | AK22: Date Range | AR22: =A22 -> 43913 | AS22: =B22*C22 -> 1587825.5 | AT22: =IF(AND($AS22 >= $BI$2, $C22 >= $BJ$2), ($C22 / $BK$2) * 100, "") | AU22: =U22 -> 43913 | AV22: =V22*W22 -> 7268724 | AW22: =IF(AND($AV22 >= $BM$2, $W22 >= $BN$2), ($W22 / $BO$2) * 100, "") | BC22: 45860 | BD22: 1.5143336e+08 | BF22: 45904 | BG22: 20333125
A23: 43914 | B23: 4720 | C23: 217 | D23: =(B23-B22)/B22 -> 0.090951115 | G23: {=_FV(A1,"Price")} -> 17.67 | H23: {=_FV(A1,"Volume")} -> 4013078 | I23: {=_FV(A1,"Change (%)",TRUE)} -> -0.002259 | J23: {=_FV(A1,"52 week high",TRUE)} -> 94.5 | K23: {=_FV(A1,"52 week low",TRUE)} -> 15.2 | P23: 10 days | Q23: =TODAY()-10 -> 46088 | U23: 43914 | V23: 3132 | W23: 2243 | X23: =(V23-V22)/V22 -> 0.08411215 | AA23: {=_FV(U1,"Price")} -> 13.23 | AB23: {=_FV(U1,"Volume")} -> 331803 | AC23: {=_FV(U1,"Change (%)",TRUE)} -> 0.003794 | AD23: {=_FV(U1,"52 week high",TRUE)} -> 63 | AE23: {=_FV(U1,"52 week low",TRUE)} -> 11.31 | AJ23: 10 days | AK23: =TODAY()-10 -> 46088 | AR23: =A23 -> 43914 | AS23: =B23*C23 -> 1024240 | AT23: =IF(AND($AS23 >= $BI$2, $C23 >= $BJ$2), ($C23 / $BK$2) * 100, "") | AU23: =U23 -> 43914 | AV23: =V23*W23 -> 7025076 | AW23: =IF(AND($AV23 >= $BM$2, $W23 >= $BN$2), ($W23 / $BO$2) * 100, "") | BC23: 45861 | BD23: 3.4156247e+08 | BF23: 45905 | BG23: 13900583
A24: 43915 | B24: 4630 | C24: 159 | D24: =(B24-B23)/B23 -> -0.019067797 | P24: 20 Days | Q24: =TODAY()-20 -> 46078 | U24: 43915 | V24: 3069 | W24: 2157 | X24: =(V24-V23)/V23 -> -0.020114943 | AJ24: 20 Days | AK24: =TODAY()-20 -> 46078 | AR24: =A24 -> 43915 | AS24: =B24*C24 -> 736170 | AT24: =IF(AND($AS24 >= $BI$2, $C24 >= $BJ$2), ($C24 / $BK$2) * 100, "") | AU24: =U24 -> 43915 | AV24: =V24*W24 -> 6619833 | AW24: =IF(AND($AV24 >= $BM$2, $W24 >= $BN$2), ($W24 / $BO$2) * 100, "") | BC24: 45862 | BD24: 1.6380474e+08 | BF24: 45908 | BG24: 16615076
A25: 43916 | B25: 4441.9 | C25: 353 | D25: =(B25-B24)/B24 -> -0.04062635 | G25: Maximum Volume Period | P25: 1 month | Q25: =TODAY()-30 -> 46068 | U25: 43916 | V25: 2961 | W25: 1921 | X25: =(V25-V24)/V24 -> -0.035190616 | AA25: Maximum Volume Period | AJ25: 1 month | AK25: =TODAY()-30 -> 46068 | AR25: =A25 -> 43916 | AS25: =B25*C25 -> 1567990.7 | AT25: =IF(AND($AS25 >= $BI$2, $C25 >= $BJ$2), ($C25 / $BK$2) * 100, "") | AU25: =U25 -> 43916 | AV25: =V25*W25 -> 5688081 | AW25: =IF(AND($AV25 >= $BM$2, $W25 >= $BN$2), ($W25 / $BO$2) * 100, "") | BC25: 45863 | BD25: 1.3945158e+08 | BF25: 45909 | BG25: 23150784
A26: 43917 | B26: 4360.1 | C26: 168 | D26: =(B26-B25)/B25 -> -0.018415543 | G26: 10 days | H26: 20 days | I26: 1 months | J26: 2 months | K26: 3 months | L26: 6 months | M26: 12 months | N26: 24 months | P26: 2 months | Q26: =TODAY()-60 -> 46038 | U26: 43917 | V26: 2898 | W26: 1499 | X26: =(V26-V25)/V25 -> -0.021276596 | AA26: 10 days | AB26: 20 days | AC26: 1 months | AD26: 2 months | AE26: 3 months | AF26: 6 months | AG26: 12 months | AH26: 24 Months | AJ26: 2 months | AK26: =TODAY()-60 -> 46038 | AR26: =A26 -> 43917 | AS26: =B26*C26 -> 732496.8 | AT26: =IF(AND($AS26 >= $BI$2, $C26 >= $BJ$2), ($C26 / $BK$2) * 100, "") | AU26: =U26 -> 43917 | AV26: =V26*W26 -> 4344102 | AW26: =IF(AND($AV26 >= $BM$2, $W26 >= $BN$2), ($W26 / $BO$2) * 100, "") | BC26: 45866 | BD26: 2.2283417e+08 | BF26: 45910 | BG26: 19774609
A27: 43920 | B27: 4460.2 | C27: 320 | D27: =(B27-B26)/B26 -> 0.022958189 | F27: Date | G27: {=_xlfn.LET( _xlpm.Data, _xlfn.DROP(_xlfn.ANCHORARRAY(A2), 1), _xlpm.Filtered, _xlfn._xlws.FILTER(_xlpm.Data, INDEX(_xlpm.Data, , 1) >= Q23), _xlfn.TAKE(_xlfn._xlws.SORT(_xlpm.Filtered, 3, -1), 1, 1) )} -> 46090 | H27: =INDEX(A:A, MATCH(_xlfn.MAXIFS(C:C, A:A, ">="&Q24), C:C, 0)) -> 46090 | I27: =INDEX(A:A, MATCH(_xlfn.MAXIFS(C:C, A:A, ">="&Q25), C:C, 0)) -> 46090 | J27: =INDEX(A:A, MATCH(_xlfn.MAXIFS(C:C, A:A, ">="&Q26), C:C, 0)) -> 46042 | K27: =INDEX(A:A, MATCH(_xlfn.MAXIFS(C:C, A:A, ">="&Q27), C:C, 0)) -> 46042 | L27: =INDEX(A:A, MATCH(_xlfn.MAXIFS(C:C, A:A, ">="&Q28), C:C, 0)) -> 46042 | M27: =INDEX(A:A, MATCH(_xlfn.MAXIFS(C:C, A:A, ">="&Q29), C:C, 0)) -> 46042 | N27: =INDEX(A:A, MATCH(_xlfn.MAXIFS(C:C, A:A, ">="&Q30), C:C, 0)) -> 46042 | P27: 3 months | Q27: =TODAY()-90 -> 46008 | U27: 43920 | V27: 2970 | W27: 1191 | X27: =(V27-V26)/V26 -> 0.02484472 | Z27: Date | AA27: {=_xlfn.LET( _xlpm.Data, _xlfn.DROP(_xlfn.ANCHORARRAY(U2), 1), _xlpm.Filtered, _xlfn._xlws.FILTER(_xlpm.Data, INDEX(_xlpm.Data, , 1) >= AK23), _xlfn.TAKE(_xlfn._xlws.SORT(_xlpm.Filtered, 3, -1), 1, 1) )} -> 46090 | AB27: =INDEX(U:U, MATCH(_xlfn.MAXIFS(W:W, U:U, ">="&AK24), W:W, 0)) -> 46084 | AC27: =INDEX(U:U, MATCH(_xlfn.MAXIFS(W:W, U:U, ">="&AK25), W:W, 0)) -> 46084 | AD27: =INDEX(U:U, MATCH(_xlfn.MAXIFS(W:W, U:U, ">="&AK26), W:W, 0)) -> 46041 | AE27: =INDEX(U:U, MATCH(_xlfn.MAXIFS(W:W, U:U, ">="&AK27), W:W, 0)) -> 46041 | AF27: =INDEX(U:U, MATCH(_xlfn.MAXIFS(W:W, U:U, ">="&AK28), W:W, 0)) -> 46041 | AG27: =INDEX(U:U, MATCH(_xlfn.MAXIFS(W:W, U:U, ">="&AK29), W:W, 0)) -> 46041 | AH27: =INDEX(U:U, MATCH(_xlfn.MAXIFS(W:W, U:U, ">="&AK30), W:W, 0)) -> 46041 | AJ27: 3 months | AK27: =TODAY()-90 -> 46008 | AR27: =A27 -> 43920 | AS27: =B27*C27 -> 1427264 | AT27: =IF(AND($AS27 >= $BI$2, $C27 >= $BJ$2), ($C27 / $BK$2) * 100, "") | AU27: =U27 -> 43920 | AV27: =V27*W27 -> 3537270 | AW27: =IF(AND($AV27 >= $BM$2, $W27 >= $BN$2), ($W27 / $BO$2) * 100, "") | BC27: 45867 | BD27: 1.6281353e+08 | BF27: 45911 | BG27: 31544176
A28: 43921 | B28: 4260 | C28: 266 | D28: =(B28-B27)/B27 -> -0.04488588 | F28: Volume recorded | G28: {=_xlfn.XLOOKUP(G27:N27, INDEX(_xlfn.ANCHORARRAY(A2), , 1), INDEX(_xlfn.ANCHORARRAY(A2), , 3), , 0, 2)} -> 23978727 | H28: 23978727 | I28: 23978727 | J28: 33500140 | K28: 33500140 | L28: 33500140 | M28: 33500140 | N28: 33500140 | P28: 6 months | Q28: =TODAY()-180 -> 45918 | U28: 43921 | V28: 2835 | W28: 2570 | X28: =(V28-V27)/V27 -> -0.045454545 | Z28: Volume recorded | AA28: {=_xlfn.XLOOKUP(AA27:AH27, INDEX(_xlfn.ANCHORARRAY(U2), , 1), INDEX(_xlfn.ANCHORARRAY(U2), , 3), , 0, 2)} -> 3688887 | AB28: 3864988 | AC28: 3864988 | AD28: 6486726 | AE28: 6486726 | AF28: 6486726 | AG28: 6486726 | AH28: 6486726 | AJ28: 6 months | AK28: =TODAY()-180 -> 45918 | AR28: =A28 -> 43921 | AS28: =B28*C28 -> 1133160 | AT28: =IF(AND($AS28 >= $BI$2, $C28 >= $BJ$2), ($C28 / $BK$2) * 100, "") | AU28: =U28 -> 43921 | AV28: =V28*W28 -> 7285950 | AW28: =IF(AND($AV28 >= $BM$2, $W28 >= $BN$2), ($W28 / $BO$2) * 100, "") | BC28: 45868 | BD28: 2.5754467e+08 | BF28: 45912 | BG28: 19252328
A29: 43922 | B29: 3910 | C29: 814 | D29: =(B29-B28)/B28 -> -0.082159624 | F29: Price recorded | G29: {=_xlfn.XLOOKUP(G27:N27, INDEX(_xlfn.ANCHORARRAY(A2), , 1), INDEX(_xlfn.ANCHORARRAY(A2), , 2), , 0, 2)} -> 18.4 | H29: 18.4 | I29: 18.4 | J29: 22.44 | K29: 22.44 | L29: 22.44 | M29: 22.44 | N29: 22.44 | P29: 12 months | Q29: =TODAY()-365 -> 45733 | U29: 43922 | V29: 2592 | W29: 2681 | X29: =(V29-V28)/V28 -> -0.085714286 | Z29: Price recorded | AA29: {=_xlfn.XLOOKUP(AA27:AH27, INDEX(_xlfn.ANCHORARRAY(U2), , 1), INDEX(_xlfn.ANCHORARRAY(U2), , 2), , 0, 2)} -> 13.73 | AB29: 13.78 | AC29: 13.78 | AD29: 14.44 | AE29: 14.44 | AF29: 14.44 | AG29: 14.44 | AH29: 14.44 | AJ29: 12 months | AK29: =TODAY()-365 -> 45733 | AR29: =A29 -> 43922 | AS29: =B29*C29 -> 3182740 | AT29: =IF(AND($AS29 >= $BI$2, $C29 >= $BJ$2), ($C29 / $BK$2) * 100, "") | AU29: =U29 -> 43922 | AV29: =V29*W29 -> 6949152 | AW29: =IF(AND($AV29 >= $BM$2, $W29 >= $BN$2), ($W29 / $BO$2) * 100, "") | BC29: 45869 | BD29: 2.3503397e+08 | BF29: 45915 | BG29: 16204873
A30: 43923 | B30: 3740 | C30: 664 | D30: =(B30-B29)/B29 -> -0.043478261 | P30: 24 Months | Q30: =TODAY()-730 -> 45368 | U30: 43923 | V30: 2479.5 | W30: 3862 | X30: =(V30-V29)/V29 -> -0.043402778 | AJ30: 24 Months | AK30: =TODAY()-730 -> 45368 | AR30: =A30 -> 43923 | AS30: =B30*C30 -> 2483360 | AT30: =IF(AND($AS30 >= $BI$2, $C30 >= $BJ$2), ($C30 / $BK$2) * 100, "") | AU30: =U30 -> 43923 | AV30: =V30*W30 -> 9575829 | AW30: =IF(AND($AV30 >= $BM$2, $W30 >= $BN$2), ($W30 / $BO$2) * 100, "") | BC30: 45870 | BD30: 1.0920322e+08 | BF30: 45916 | BG30: 18594423
A31: 43924 | B31: 4180 | C31: 560 | D31: =(B31-B30)/B30 -> 0.11764706 | U31: 43924 | V31: 2781 | W31: 2996 | X31: =(V31-V30)/V30 -> 0.1215971 | AR31: =A31 -> 43924 | AS31: =B31*C31 -> 2340800 | AT31: =IF(AND($AS31 >= $BI$2, $C31 >= $BJ$2), ($C31 / $BK$2) * 100, "") | AU31: =U31 -> 43924 | AV31: =V31*W31 -> 8331876 | AW31: =IF(AND($AV31 >= $BM$2, $W31 >= $BN$2), ($W31 / $BO$2) * 100, "") | BC31: 45873 | BD31: 2.7016885e+08 | BF31: 45917 | BG31: 14982679
A32: 43927 | B32: 4690 | C32: 434 | D32: =(B32-B31)/B31 -> 0.12200957 | G32: Maximum Price Period | U32: 43927 | V32: 3114 | W32: 3723 | X32: =(V32-V31)/V31 -> 0.1197411 | AA32: Maximum Price Period | AR32: =A32 -> 43927 | AS32: =B32*C32 -> 2035460 | AT32: =IF(AND($AS32 >= $BI$2, $C32 >= $BJ$2), ($C32 / $BK$2) * 100, "") | AU32: =U32 -> 43927 | AV32: =V32*W32 -> 11593422 | AW32: =IF(AND($AV32 >= $BM$2, $W32 >= $BN$2), ($W32 / $BO$2) * 100, "") | BC32: 45874 | BD32: 1.588778e+08 | BF32: 45918 | BG32: 28369766
A33: 43928 | B33: 5450 | C33: 666 | D33: =(B33-B32)/B32 -> 0.16204691 | G33: 10 days | H33: 20 days | I33: 1 months | J33: 2 months | K33: 3 months | L33: 6 months | M33: 12 months | N33: 24 months | U33: 43928 | V33: 3591 | W33: 2738 | X33: =(V33-V32)/V32 -> 0.15317919 | AA33: 10 days | AB33: 20 days | AC33: 1 months | AD33: 2 months | AE33: 3 months | AF33: 6 months | AG33: 12 months | AH33: 24 Months | AR33: =A33 -> 43928 | AS33: =B33*C33 -> 3629700 | AT33: =IF(AND($AS33 >= $BI$2, $C33 >= $BJ$2), ($C33 / $BK$2) * 100, "") | AU33: =U33 -> 43928 | AV33: =V33*W33 -> 9832158 | AW33: =IF(AND($AV33 >= $BM$2, $W33 >= $BN$2), ($W33 / $BO$2) * 100, "") | BC33: 45875 | BD33: 1.4214153e+08 | BF33: 45919 | BG33: 14503501
A34: 43929 | B34: 4970 | C34: 556 | D34: =(B34-B33)/B33 -> -0.088073394 | F34: Date | G34: {=_xlfn.LET( _xlpm.Data, _xlfn.DROP(_xlfn.ANCHORARRAY(A2), 1), _xlpm.Filtered, _xlfn._xlws.FILTER(_xlpm.Data, INDEX(_xlpm.Data, , 1) >= Q23), _xlfn.TAKE(_xlfn._xlws.SORT(_xlpm.Filtered, 2, -1), 1, 1) )} -> 46093 | H34: {=_xlfn.LET( _xlpm.Data, _xlfn.DROP(_xlfn.ANCHORARRAY(A2), 1), _xlpm.Filtered, _xlfn._xlws.FILTER(_xlpm.Data, INDEX(_xlpm.Data, , 1) >= Q24), _xlfn.TAKE(_xlfn._xlws.SORT(_xlpm.Filtered, 2, -1), 1, 1) )} -> 46093 | I34: {=_xlfn.LET( _xlpm.Data, _xlfn.DROP(_xlfn.ANCHORARRAY(A2), 1), _xlpm.Filtered, _xlfn._xlws.FILTER(_xlpm.Data, INDEX(_xlpm.Data, , 1) >= Q25), _xlfn.TAKE(_xlfn._xlws.SORT(_xlpm.Filtered, 2, -1), 1, 1) )} -> 46093 | J34: {=_xlfn.LET( _xlpm.Data, _xlfn.DROP(_xlfn.ANCHORARRAY(A2), 1), _xlpm.Filtered, _xlfn._xlws.FILTER(_xlpm.Data, INDEX(_xlpm.Data, , 1) >= Q26), _xlfn.TAKE(_xlfn._xlws.SORT(_xlpm.Filtered, 2, -1), 1, 1) )} -> 46052 | K34: {=_xlfn.LET( _xlpm.Data, _xlfn.DROP(_xlfn.ANCHORARRAY(A2), 1), _xlpm.Filtered, _xlfn._xlws.FILTER(_xlpm.Data, INDEX(_xlpm.Data, , 1) >= Q27), _xlfn.TAKE(_xlfn._xlws.SORT(_xlpm.Filtered, 2, -1), 1, 1) )} -> 46052 | L34: {=_xlfn.LET( _xlpm.Data, _xlfn.DROP(_xlfn.ANCHORARRAY(A2), 1), _xlpm.Filtered, _xlfn._xlws.FILTER(_xlpm.Data, INDEX(_xlpm.Data, , 1) >= Q28), _xlfn.TAKE(_xlfn._xlws.SORT(_xlpm.Filtered, 2, -1), 1, 1) )} -> 45996 | M34: {=_xlfn.LET( _xlpm.Data, _xlfn.DROP(_xlfn.ANCHORARRAY(A2), 1), _xlpm.Filtered, _xlfn._xlws.FILTER(_xlpm.Data, INDEX(_xlpm.Data, , 1) >= Q29), _xlfn.TAKE(_xlfn._xlws.SORT(_xlpm.Filtered, 2, -1), 1, 1) )} -> 45735 | N34: {=_xlfn.LET( _xlpm.Data, _xlfn.DROP(_xlfn.ANCHORARRAY(A2), 1), _xlpm.Filtered, _xlfn._xlws.FILTER(_xlpm.Data, INDEX(_xlpm.Data, , 1) >= Q30), _xlfn.TAKE(_xlfn._xlws.SORT(_xlpm.Filtered, 2, -1), 1, 1) )} -> 45454 | U34: 43929 | V34: 3249 | W34: 2807 | X34: =(V34-V33)/V33 -> -0.095238095 | Z34: Date | AA34: {=_xlfn.LET( _xlpm.Data, _xlfn.DROP(_xlfn.ANCHORARRAY(U2), 1), _xlpm.Filtered, _xlfn._xlws.FILTER(_xlpm.Data, INDEX(_xlpm.Data, , 1) >= AK23), _xlfn.TAKE(_xlfn._xlws.SORT(_xlpm.Filtered, 2, -1), 1, 1) )} -> 46093 | AB34: {=_xlfn.LET( _xlpm.Data, _xlfn.DROP(_xlfn.ANCHORARRAY(U2), 1), _xlpm.Filtered, _xlfn._xlws.FILTER(_xlpm.Data, INDEX(_xlpm.Data, , 1) >= AK24), _xlfn.TAKE(_xlfn._xlws.SORT(_xlpm.Filtered, 2, -1), 1, 1) )} -> 46093 | AC34: {=_xlfn.LET( _xlpm.Data, _xlfn.DROP(_xlfn.ANCHORARRAY(U2), 1), _xlpm.Filtered, _xlfn._xlws.FILTER(_xlpm.Data, INDEX(_xlpm.Data, , 1) >= AK25), _xlfn.TAKE(_xlfn._xlws.SORT(_xlpm.Filtered, 2, -1), 1, 1) )} -> 46093 | AD34: {=_xlfn.LET( _xlpm.Data, _xlfn.DROP(_xlfn.ANCHORARRAY(U2), 1), _xlpm.Filtered, _xlfn._xlws.FILTER(_xlpm.Data, INDEX(_xlpm.Data, , 1) >= AK26), _xlfn.TAKE(_xlfn._xlws.SORT(_xlpm.Filtered, 2, -1), 1, 1) )} -> 46052 | AE34: {=_xlfn.LET( _xlpm.Data, _xlfn.DROP(_xlfn.ANCHORARRAY(U2), 1), _xlpm.Filtered, _xlfn._xlws.FILTER(_xlpm.Data, INDEX(_xlpm.Data, , 1) >= AK27), _xlfn.TAKE(_xlfn._xlws.SORT(_xlpm.Filtered, 2, -1), 1, 1) )} -> 46052 | AF34: {=_xlfn.LET( _xlpm.Data, _xlfn.DROP(_xlfn.ANCHORARRAY(U2), 1), _xlpm.Filtered, _xlfn._xlws.FILTER(_xlpm.Data, INDEX(_xlpm.Data, , 1) >= AK28), _xlfn.TAKE(_xlfn._xlws.SORT(_xlpm.Filtered, 2, -1), 1, 1) )} -> 46052 | AG34: {=_xlfn.LET( _xlpm.Data, _xlfn.DROP(_xlfn.ANCHORARRAY(U2), 1), _xlpm.Filtered, _xlfn._xlws.FILTER(_xlpm.Data, INDEX(_xlpm.Data, , 1) >= AK29), _xlfn.TAKE(_xlfn._xlws.SORT(_xlpm.Filtered, 2, -1), 1, 1) )} -> 45735 | AH34: {=_xlfn.LET( _xlpm.Data, _xlfn.DROP(_xlfn.ANCHORARRAY(U2), 1), _xlpm.Filtered, _xlfn._xlws.FILTER(_xlpm.Data, INDEX(_xlpm.Data, , 1) >= AK30), _xlfn.TAKE(_xlfn._xlws.SORT(_xlpm.Filtered, 2, -1), 1, 1) )} -> 45454 | AR34: =A34 -> 43929 | AS34: =B34*C34 -> 2763320 | AT34: =IF(AND($AS34 >= $BI$2, $C34 >= $BJ$2), ($C34 / $BK$2) * 100, "") | AU34: =U34 -> 43929 | AV34: =V34*W34 -> 9119943 | AW34: =IF(AND($AV34 >= $BM$2, $W34 >= $BN$2), ($W34 / $BO$2) * 100, "") | BC34: 45876 | BD34: 1.468209e+08 | BF34: 45922 | BG34: 20218622
A35: 43930 | B35: 4800 | C35: 320 | D35: =(B35-B34)/B34 -> -0.034205231 | F35: Volume recorded | G35: {=_xlfn.XLOOKUP(G34:N34, INDEX(_xlfn.ANCHORARRAY(A2), , 1), INDEX(_xlfn.ANCHORARRAY(A2), , 3), , 0, 2)} -> 11540327 | H35: 11540327 | I35: 11540327 | J35: 18659908 | K35: 18659908 | L35: 16625164 | M35: 1773345 | N35: 1941279 | U35: 43930 | V35: 3118.5 | W35: 3007 | X35: =(V35-V34)/V34 -> -0.040166205 | Z35: Volume recorded | AA35: {=_xlfn.XLOOKUP(AA34:AH34, INDEX(_xlfn.ANCHORARRAY(U2), , 1), INDEX(_xlfn.ANCHORARRAY(U2), , 3), , 0, 2)} -> 1558382 | AB35: 1558382 | AC35: 1558382 | AD35: 2386268 | AE35: 2386268 | AF35: 2386268 | AG35: 185694 | AH35: 568873 | AR35: =A35 -> 43930 | AS35: =B35*C35 -> 1536000 | AT35: =IF(AND($AS35 >= $BI$2, $C35 >= $BJ$2), ($C35 / $BK$2) * 100, "") | AU35: =U35 -> 43930 | AV35: =V35*W35 -> 9377329.5 | AW35: =IF(AND($AV35 >= $BM$2, $W35 >= $BN$2), ($W35 / $BO$2) * 100, "") | BC35: 45877 | BD35: 1.7333316e+08 | BF35: 45923 | BG35: 18053693
A36: 43934 | B36: 4890 | C36: 350 | D36: =(B36-B35)/B35 -> 0.01875 | F36: Price recorded | G36: {=_xlfn.XLOOKUP(G34:N34, INDEX(_xlfn.ANCHORARRAY(A2), , 1), INDEX(_xlfn.ANCHORARRAY(A2), , 2), , 0, 2)} -> 20.3 | H36: 20.3 | I36: 20.3 | J36: 40.67 | K36: 40.67 | L36: 43.62 | M36: 92.37 | N36: 118.3 | U36: 43934 | V36: 3204 | W36: 2413 | X36: =(V36-V35)/V35 -> 0.027417027 | Z36: Price recorded | AA36: {=_xlfn.XLOOKUP(AA34:AH34, INDEX(_xlfn.ANCHORARRAY(U2), , 1), INDEX(_xlfn.ANCHORARRAY(U2), , 2), , 0, 2)} -> 15.11 | AB36: 15.11 | AC36: 15.11 | AD36: 30.26 | AE36: 30.26 | AF36: 30.26 | AG36: 61.91 | AH36: 78.48 | AR36: =A36 -> 43934 | AS36: =B36*C36 -> 1711500 | AT36: =IF(AND($AS36 >= $BI$2, $C36 >= $BJ$2), ($C36 / $BK$2) * 100, "") | AU36: =U36 -> 43934 | AV36: =V36*W36 -> 7731252 | AW36: =IF(AND($AV36 >= $BM$2, $W36 >= $BN$2), ($W36 / $BO$2) * 100, "") | BC36: 45880 | BD36: 1.1435345e+08 | BF36: 45924 | BG36: 16259585
A37: 43935 | B37: 4520 | C37: 369 | D37: =(B37-B36)/B36 -> -0.075664622 | U37: 43935 | V37: 2979 | W37: 1940 | X37: =(V37-V36)/V36 -> -0.070224719 | AR37: =A37 -> 43935 | AS37: =B37*C37 -> 1667880 | AT37: =IF(AND($AS37 >= $BI$2, $C37 >= $BJ$2), ($C37 / $BK$2) * 100, "") | AU37: =U37 -> 43935 | AV37: =V37*W37 -> 5779260 | AW37: =IF(AND($AV37 >= $BM$2, $W37 >= $BN$2), ($W37 / $BO$2) * 100, "") | BC37: 45881 | BD37: 3.1323911e+08 | BF37: 45925 | BG37: 33011332
A38: 43936 | B38: 4200 | C38: 656 | D38: =(B38-B37)/B37 -> -0.07079646 | F38: Stock Split History | G38: Ratio | U38: 43936 | V38: 2727 | W38: 2180 | X38: =(V38-V37)/V37 -> -0.084592145 | Z38: Stock Split History | AA38: Ratio | AR38: =A38 -> 43936 | AS38: =B38*C38 -> 2755200 | AT38: =IF(AND($AS38 >= $BI$2, $C38 >= $BJ$2), ($C38 / $BK$2) * 100, "") | AU38: =U38 -> 43936 | AV38: =V38*W38 -> 5944860 | AW38: =IF(AND($AV38 >= $BM$2, $W38 >= $BN$2), ($W38 / $BO$2) * 100, "") | BC38: 45882 | BD38: 1.4201322e+08 | BF38: 45926 | BG38: 23565288
A39: 43937 | B39: 4600 | C39: 1102 | D39: =(B39-B38)/B38 -> 0.095238095 | F39: 41040 | G39: 0.045138889 | U39: 43937 | V39: 3033 | W39: 3441 | X39: =(V39-V38)/V38 -> 0.11221122 | Z39: 39918 | AA39: 0.044444444 | AR39: =A39 -> 43937 | AS39: =B39*C39 -> 5069200 | AT39: =IF(AND($AS39 >= $BI$2, $C39 >= $BJ$2), ($C39 / $BK$2) * 100, "") | AU39: =U39 -> 43937 | AV39: =V39*W39 -> 10436553 | AW39: =IF(AND($AV39 >= $BM$2, $W39 >= $BN$2), ($W39 / $BO$2) * 100, "") | BC39: 45883 | BD39: 1.5177347e+08 | BF39: 45929 | BG39: 16805622
A40: 43938 | B40: 4770 | C40: 405 | D40: =(B40-B39)/B39 -> 0.036956522 | F40: 42144 | G40: 0.044444444 | U40: 43938 | V40: 3231 | W40: 3187 | X40: =(V40-V39)/V39 -> 0.065281899 | Z40: 40072 | AA40: 0.045138889 | AR40: =A40 -> 43938 | AS40: =B40*C40 -> 1931850 | AT40: =IF(AND($AS40 >= $BI$2, $C40 >= $BJ$2), ($C40 / $BK$2) * 100, "") | AU40: =U40 -> 43938 | AV40: =V40*W40 -> 10297197 | AW40: =IF(AND($AV40 >= $BM$2, $W40 >= $BN$2), ($W40 / $BO$2) * 100, "") | BC40: 45884 | BD40: 1.8312996e+08 | BF40: 45930 | BG40: 23114842
A41: 43941 | B41: 5495 | C41: 896 | D41: =(B41-B40)/B40 -> 0.15199161 | F41: 43179 | G41: 0.045138889 | U41: 43941 | V41: 3762 | W41: 4640 | X41: =(V41-V40)/V40 -> 0.1643454 | Z41: 40490 | AA41: 0.043055556 | AR41: =A41 -> 43941 | AS41: =B41*C41 -> 4923520 | AT41: =IF(AND($AS41 >= $BI$2, $C41 >= $BJ$2), ($C41 / $BK$2) * 100, "") | AU41: =U41 -> 43941 | AV41: =V41*W41 -> 17455680 | AW41: =IF(AND($AV41 >= $BM$2, $W41 >= $BN$2), ($W41 / $BO$2) * 100, "") | BC41: 45887 | BD41: 1.3945646e+08 | BF41: 45931 | BG41: 45808824
A42: 43942 | B42: 5220 | C42: 1706 | D42: =(B42-B41)/B41 -> -0.050045496 | F42: 43942 | G42: 0.048611111 | U42: 43942 | V42: 3465 | W42: 3865 | X42: =(V42-V41)/V41 -> -0.078947368 | Z42: 40870 | AA42: 0.044444444 | AR42: =A42 -> 43942 | AS42: =B42*C42 -> 8905320 | AT42: =IF(AND($AS42 >= $BI$2, $C42 >= $BJ$2), ($C42 / $BK$2) * 100, "") | AU42: =U42 -> 43942 | AV42: =V42*W42 -> 13392225 | AW42: =IF(AND($AV42 >= $BM$2, $W42 >= $BN$2), ($W42 / $BO$2) * 100, "") | BC42: 45888 | BD42: 2.536748e+08 | BF42: 45932 | BG42: 31541481
A43: 43943 | B43: 5500 | C43: 668 | D43: =(B43-B42)/B42 -> 0.053639847 | F43: 45100 | G43: 0.055555556 | U43: 43943 | V43: 3699 | W43: 3250 | X43: =(V43-V42)/V42 -> 0.067532468 | Z43: 41012 | AA43: 0.044444444 | AR43: =A43 -> 43943 | AS43: =B43*C43 -> 3674000 | AT43: =IF(AND($AS43 >= $BI$2, $C43 >= $BJ$2), ($C43 / $BK$2) * 100, "") | AU43: =U43 -> 43943 | AV43: =V43*W43 -> 12021750 | AW43: =IF(AND($AV43 >= $BM$2, $W43 >= $BN$2), ($W43 / $BO$2) * 100, "") | BC43: 45889 | BD43: 1.3161213e+08 | BF43: 45933 | BG43: 27510267
A44: 43944 | B44: 5140 | C44: 386 | D44: =(B44-B43)/B43 -> -0.065454545 | F44: 45603 | G44: 0.045138889 | L44: Start Date | U44: 43944 | V44: 3339 | W44: 5800 | X44: =(V44-V43)/V43 -> -0.097323601 | Z44: 42334 | AA44: 0.048611111 | AF44: Start Date | AR44: =A44 -> 43944 | AS44: =B44*C44 -> 1984040 | AT44: =IF(AND($AS44 >= $BI$2, $C44 >= $BJ$2), ($C44 / $BK$2) * 100, "") | AU44: =U44 -> 43944 | AV44: =V44*W44 -> 19366200 | AW44: =IF(AND($AV44 >= $BM$2, $W44 >= $BN$2), ($W44 / $BO$2) * 100, "") | BC44: 45890 | BD44: 1.5494177e+08 | BF44: 45936 | BG44: 25650207
A45: 43945 | B45: 4908 | C45: 985 | D45: =(B45-B44)/B44 -> -0.045136187 | L45: 45831 | U45: 43945 | V45: 3096 | W45: 3272 | X45: =(V45-V44)/V44 -> -0.07277628 | Z45: 43528 | AA45: 0.045138889 | AF45: 45875 | AR45: =A45 -> 43945 | AS45: =B45*C45 -> 4834380 | AT45: =IF(AND($AS45 >= $BI$2, $C45 >= $BJ$2), ($C45 / $BK$2) * 100, "") | AU45: =U45 -> 43945 | AV45: =V45*W45 -> 10130112 | AW45: =IF(AND($AV45 >= $BM$2, $W45 >= $BN$2), ($W45 / $BO$2) * 100, "") | BC45: 45891 | BD45: 1.8797377e+08 | BF45: 45937 | BG45: 28088339
...

Sheet KOLD & HND
A1: #VALUE! | F1: Average Volume | M1: Volume Moving Average ( VMA ) | U1: #VALUE! | Z1: Average Volume | AG1: Volume Moving Average ( VMA ) | AR1: $ Value Traded KOLD | AU1: $ Value Traded HND | BD1: {=_xlfn._xlws.FILTER(BB4000:BC6000, BB4000:BB6000<>"")} -> Filtered Date KOLD | BE1: Filtered Value KOLD | BG1: {=_xlfn._xlws.FILTER(BE4000:BF6000, BE4000:BE6000<>"")} -> Filtered Date HND | BH1: Filtered Value HND
A2: {=_xlfn.STOCKHISTORY(A1,DATE(2020,2,25),TODAY(),0,1,0,1,5)} -> Date | B2: Close | C2: Volume | D2: % Change | F2: 10 days | G2: 20 Days | H2: 1 month | I2: 3 months | J2: 6 months | K2: 1 year | M2: 10 Days | N2: 20 Days | O2: 50 Days | P2: 100 Days | Q2: 200 Days | R2: 360 Days | U2: {=_xlfn.STOCKHISTORY(U1,DATE(2020,2,25),TODAY(),0,1,0,1,5)} -> Date | V2: Close | W2: Volume | X2: % Change | Z2: 10 days | AA2: 20 Days | AB2: 1 month | AC2: 3 months | AD2: 6 months | AE2: 1 year | AG2: 10 Days | AH2: 20 Days | AI2: 50 Days | AJ2: 100 Days | AK2: 200 Days | AL2: 360 Days | AR2: Date | AS2: Value | AT2: % Vol Percentile | AU2: Date | AV2: Value | AW2: % Vol Percentile | BD2: 45076 | BE2: 1.3793132e+08 | BG2: 45323 | BH2: 23105077 | BI2: =_xlfn.PERCENTILE.INC(AS:AS, 0.9) -> 2.0363368e+08 | BJ2: =_xlfn.PERCENTILE.INC(C:C, 0.9) -> 12338209 | BK2: =MAX(C:C) -> 97627146 | BM2: =_xlfn.PERCENTILE.INC(AV3:AV5000, 0.9) -> 35584728 | BN2: =_xlfn.PERCENTILE.INC(W3:W5000, 0.9) -> 4542518.8 | BO2: =MAX(W3:W5000) -> 26722821
A3: 43886 | B3: 526.7 | C3: 2274 | D3: - | F3: =AVERAGE(_xlfn.TAKE(INDEX(_xlfn.ANCHORARRAY(A2), , 3), -10)) -> 8604151.5 | G3: =AVERAGE(_xlfn.TAKE(INDEX(_xlfn.ANCHORARRAY(A2), , 3), -20)) -> 7334077.5 | H3: =AVERAGE(_xlfn.TAKE(INDEX(_xlfn.ANCHORARRAY(A2), , 3), -30)) -> 9799045.1 | I3: =AVERAGE(_xlfn.TAKE(INDEX(_xlfn.ANCHORARRAY(A2), , 3), -90)) -> 9699254.5 | J3: =AVERAGE(_xlfn.TAKE(INDEX(_xlfn.ANCHORARRAY(A2), , 3), -180)) -> 6875682.1 | K3: =AVERAGE(_xlfn.TAKE(INDEX(_xlfn.ANCHORARRAY(A2), , 3), -365)) -> 6255991.5 | M3: {=_xlfn.LET( _xlpm.Last10, _xlfn.TAKE(_xlfn.ANCHORARRAY(A2), -10), _xlpm.Price, INDEX(_xlpm.Last10, , 2), _xlpm.Vol, INDEX(_xlpm.Last10, , 3), SUM(_xlpm.Price * _xlpm.Vol) / SUM(_xlpm.Vol) )} -> 19.673033 | N3: {=_xlfn.LET( _xlpm.Last20, _xlfn.TAKE(_xlfn.ANCHORARRAY(A2), -20), _xlpm.Price, INDEX(_xlpm.Last20, , 2), _xlpm.Vol, INDEX(_xlpm.Last20, , 3), SUM(_xlpm.Price * _xlpm.Vol) / SUM(_xlpm.Vol) )} -> 20.828905 | O3: {=_xlfn.LET( _xlpm.Last50, _xlfn.TAKE(_xlfn.ANCHORARRAY(A2), -50), _xlpm.Price, INDEX(_xlpm.Last50, , 2), _xlpm.Vol, INDEX(_xlpm.Last50, , 3), SUM(_xlpm.Price * _xlpm.Vol) / SUM(_xlpm.Vol) )} -> 21.264433 | P3: {=_xlfn.LET( _xlpm.Last100, _xlfn.TAKE(_xlfn.ANCHORARRAY(A2), -100), _xlpm.Price, INDEX(_xlpm.Last100, , 2), _xlpm.Vol, INDEX(_xlpm.Last100, , 3), SUM(_xlpm.Price * _xlpm.Vol) / SUM(_xlpm.Vol) )} -> 23.956111 | Q3: {=_xlfn.LET( _xlpm.Last200, _xlfn.TAKE(_xlfn.ANCHORARRAY(A2), -200), _xlpm.Price, INDEX(_xlpm.Last200, , 2), _xlpm.Vol, INDEX(_xlpm.Last200, , 3), SUM(_xlpm.Price * _xlpm.Vol) / SUM(_xlpm.Vol) )} -> 25.793703 | R3: {=_xlfn.LET( _xlpm.Last360, _xlfn.TAKE(_xlfn.ANCHORARRAY(A2), -360), _xlpm.Price, INDEX(_xlpm.Last360, , 2), _xlpm.Vol, INDEX(_xlpm.Last360, , 3), SUM(_xlpm.Price * _xlpm.Vol) / SUM(_xlpm.Vol) )} -> 27.356339 | U3: 43886 | V3: 34.325 | W3: 209216 | X3: - | Z3: =AVERAGE(_xlfn.TAKE(INDEX(_xlfn.ANCHORARRAY(U2), , 3), -10)) -> 5946551.3 | AA3: =AVERAGE(_xlfn.TAKE(INDEX(_xlfn.ANCHORARRAY(U2), , 3), -20)) -> 5924091.9 | AB3: =AVERAGE(_xlfn.TAKE(INDEX(_xlfn.ANCHORARRAY(U2), , 3), -30)) -> 7273293.3 | AC3: =AVERAGE(_xlfn.TAKE(INDEX(_xlfn.ANCHORARRAY(U2), , 3), -90)) -> 6498564.5 | AD3: =AVERAGE(_xlfn.TAKE(INDEX(_xlfn.ANCHORARRAY(U2), , 3), -180)) -> 4536059.6 | AE3: =AVERAGE(_xlfn.TAKE(INDEX(_xlfn.ANCHORARRAY(U2), , 3), -365)) -> 3899596.4 | AG3: {=_xlfn.LET( _xlpm.Last10, _xlfn.TAKE(_xlfn.ANCHORARRAY(U2), -10), _xlpm.Price, INDEX(_xlpm.Last10, , 2), _xlpm.Vol, INDEX(_xlpm.Last10, , 3), SUM(_xlpm.Price * _xlpm.Vol) / SUM(_xlpm.Vol) )} -> 3.9164899 | AH3: {=_xlfn.LET( _xlpm.Last20, _xlfn.TAKE(_xlfn.ANCHORARRAY(U2), -20), _xlpm.Price, INDEX(_xlpm.Last20, , 2), _xlpm.Vol, INDEX(_xlpm.Last20, , 3), SUM(_xlpm.Price * _xlpm.Vol) / SUM(_xlpm.Vol) )} -> 4.2152145 | AI3: {=_xlfn.LET( _xlpm.Last50, _xlfn.TAKE(_xlfn.ANCHORARRAY(U2), -50), _xlpm.Price, INDEX(_xlpm.Last50, , 2), _xlpm.Vol, INDEX(_xlpm.Last50, , 3), SUM(_xlpm.Price * _xlpm.Vol) / SUM(_xlpm.Vol) )} -> 4.4706547 | AJ3: {=_xlfn.LET( _xlpm.Last100, _xlfn.TAKE(_xlfn.ANCHORARRAY(U2), -100), _xlpm.Price, INDEX(_xlpm.Last100, , 2), _xlpm.Vol, INDEX(_xlpm.Last100, , 3), SUM(_xlpm.Price * _xlpm.Vol) / SUM(_xlpm.Vol) )} -> 5.2121131 | AK3: {=_xlfn.LET( _xlpm.Last200, _xlfn.TAKE(_xlfn.ANCHORARRAY(U2), -200), _xlpm.Price, INDEX(_xlpm.Last200, , 2), _xlpm.Vol, INDEX(_xlpm.Last200, , 3), SUM(_xlpm.Price * _xlpm.Vol) / SUM(_xlpm.Vol) )} -> 6.0676497 | AL3: {=_xlfn.LET( _xlpm.Last360, _xlfn.TAKE(_xlfn.ANCHORARRAY(U2), -360), _xlpm.Price, INDEX(_xlpm.Last360, , 2), _xlpm.Vol, INDEX(_xlpm.Last360, , 3), SUM(_xlpm.Price * _xlpm.Vol) / SUM(_xlpm.Vol) )} -> 7.0880777 | AR3: =A3 -> 43886 | AS3: =B3*C3 -> 1197715.8 | AT3: =IF(AND($AS3 >= $BI$2, $C3 >= $BJ$2), ($C3 / $BK$2) * 100, "") | AU3: =U3 -> 43886 | AV3: =V3*W3 -> 7181339.2 | AW3: =IF(AND($AV3 >= $BM$2, $W3 >= $BN$2), ($W3 / $BO$2) * 100, "") | BD3: 45077 | BE3: 1.3355128e+08 | BG3: 45324 | BH3: 30994973
A4: 43887 | B4: 540.2 | C4: 2115 | D4: =(B4-B3)/B3 -> 0.025631289 | U4: 43887 | V4: 35.25 | W4: 268665 | X4: =(V4-V3)/V3 -> 0.026948288 | AR4: =A4 -> 43887 | AS4: =B4*C4 -> 1142523 | AT4: =IF(AND($AS4 >= $BI$2, $C4 >= $BJ$2), ($C4 / $BK$2) * 100, "") | AU4: =U4 -> 43887 | AV4: =V4*W4 -> 9470441.2 | AW4: =IF(AND($AV4 >= $BM$2, $W4 >= $BN$2), ($W4 / $BO$2) * 100, "") | BD4: 45078 | BE4: 1.4710474e+08 | BG4: 45327 | BH4: 19320150
A5: 43888 | B5: 584 | C5: 3256 | D5: =(B5-B4)/B4 -> 0.081081081 | U5: 43888 | V5: 38.725 | W5: 275410 | X5: =(V5-V4)/V4 -> 0.09858156 | AR5: =A5 -> 43888 | AS5: =B5*C5 -> 1901504 | AT5: =IF(AND($AS5 >= $BI$2, $C5 >= $BJ$2), ($C5 / $BK$2) * 100, "") | AU5: =U5 -> 43888 | AV5: =V5*W5 -> 10665252 | AW5: =IF(AND($AV5 >= $BM$2, $W5 >= $BN$2), ($W5 / $BO$2) * 100, "") | AZ5: =IF(AND($AS3 >= $BI$2, $C3 >= $BJ$2), ($C3 / $BK$2) * 100, "") | BD5: 45079 | BE5: 90138377 | BG5: 45328 | BH5: 18998114
A6: 43889 | B6: 619.6 | C6: 3014 | D6: =(B6-B5)/B5 -> 0.060958904 | U6: 43889 | V6: 40.575 | W6: 287309 | X6: =(V6-V5)/V5 -> 0.047772757 | AR6: =A6 -> 43889 | AS6: =B6*C6 -> 1867474.4 | AT6: =IF(AND($AS6 >= $BI$2, $C6 >= $BJ$2), ($C6 / $BK$2) * 100, "") | AU6: =U6 -> 43889 | AV6: =V6*W6 -> 11657563 | AW6: =IF(AND($AV6 >= $BM$2, $W6 >= $BN$2), ($W6 / $BO$2) * 100, "") | BD6: 45082 | BE6: 1.0074302e+08 | BG6: 45329 | BH6: 12628372
A7: 43892 | B7: 576.6 | C7: 2914 | D7: =(B7-B6)/B6 -> -0.069399613 | U7: 43892 | V7: 37.475 | W7: 431350 | X7: =(V7-V6)/V6 -> -0.076401725 | AR7: =A7 -> 43892 | AS7: =B7*C7 -> 1680212.4 | AT7: =IF(AND($AS7 >= $BI$2, $C7 >= $BJ$2), ($C7 / $BK$2) * 100, "") | AU7: =U7 -> 43892 | AV7: =V7*W7 -> 16164841 | AW7: =IF(AND($AV7 >= $BM$2, $W7 >= $BN$2), ($W7 / $BO$2) * 100, "") | BD7: 45083 | BE7: 79221940 | BG7: 45330 | BH7: 24359798
A8: 43893 | B8: 549.692 | C8: 5069 | D8: =(B8-B7)/B7 -> -0.046666667 | U8: 43893 | V8: 35.5 | W8: 640152 | X8: =(V8-V7)/V7 -> -0.052701801 | AR8: =A8 -> 43893 | AS8: =B8*C8 -> 2786388.7 | AT8: =IF(AND($AS8 >= $BI$2, $C8 >= $BJ$2), ($C8 / $BK$2) * 100, "") | AU8: =U8 -> 43893 | AV8: =V8*W8 -> 22725396 | AW8: =IF(AND($AV8 >= $BM$2, $W8 >= $BN$2), ($W8 / $BO$2) * 100, "") | BD8: 45084 | BE8: 1.1681604e+08 | BG8: 45331 | BH8: 13190384
A9: 43894 | B9: 529.2 | C9: 1563 | D9: =(B9-B8)/B8 -> -0.037279058 | U9: 43894 | V9: 34.15 | W9: 264131 | X9: =(V9-V8)/V8 -> -0.038028169 | AR9: =A9 -> 43894 | AS9: =B9*C9 -> 827139.6 | AT9: =IF(AND($AS9 >= $BI$2, $C9 >= $BJ$2), ($C9 / $BK$2) * 100, "") | AU9: =U9 -> 43894 | AV9: =V9*W9 -> 9020073.7 | AW9: =IF(AND($AV9 >= $BM$2, $W9 >= $BN$2), ($W9 / $BO$2) * 100, "") | BD9: 45085 | BE9: 1.198701e+08 | BG9: 45334 | BH9: 20471289
A10: 43895 | B10: 566.8 | C10: 2304 | D10: =(B10-B9)/B9 -> 0.071050642 | U10: 43895 | V10: 36.85 | W10: 328496 | X10: =(V10-V9)/V9 -> 0.079062958 | AR10: =A10 -> 43895 | AS10: =B10*C10 -> 1305907.2 | AT10: =IF(AND($AS10 >= $BI$2, $C10 >= $BJ$2), ($C10 / $BK$2) * 100, "") | AU10: =U10 -> 43895 | AV10: =V10*W10 -> 12105078 | AW10: =IF(AND($AV10 >= $BM$2, $W10 >= $BN$2), ($W10 / $BO$2) * 100, "") | BD10: 45086 | BE10: 1.1377743e+08 | BG10: 45335 | BH10: 22213962
A11: 43896 | B11: 592.2 | C11: 3685 | D11: =(B11-B10)/B10 -> 0.044812985 | U11: 43896 | V11: 38.5 | W11: 409889 | X11: =(V11-V10)/V10 -> 0.044776119 | AR11: =A11 -> 43896 | AS11: =B11*C11 -> 2182257 | AT11: =IF(AND($AS11 >= $BI$2, $C11 >= $BJ$2), ($C11 / $BK$2) * 100, "") | AU11: =U11 -> 43896 | AV11: =V11*W11 -> 15780726 | AW11: =IF(AND($AV11 >= $BM$2, $W11 >= $BN$2), ($W11 / $BO$2) * 100, "") | BD11: 45089 | BE11: 1.1154568e+08 | BG11: 45336 | BH11: 14597187
A12: 43899 | B12: 530.313 | C12: 7863 | D12: =(B12-B11)/B11 -> -0.10450355 | U12: 43899 | V12: 34.125 | W12: 473936 | X12: =(V12-V11)/V11 -> -0.11363636 | AR12: =A12 -> 43899 | AS12: =B12*C12 -> 4169851.1 | AT12: =IF(AND($AS12 >= $BI$2, $C12 >= $BJ$2), ($C12 / $BK$2) * 100, "") | AU12: =U12 -> 43899 | AV12: =V12*W12 -> 16173066 | AW12: =IF(AND($AV12 >= $BM$2, $W12 >= $BN$2), ($W12 / $BO$2) * 100, "") | BD12: 45090 | BE12: 85950441 | BG12: 45337 | BH12: 17934505
A13: 43900 | B13: 456.35 | C13: 8879 | D13: =(B13-B12)/B12 -> -0.13947046 | U13: 43900 | V13: 29.55 | W13: 769319 | X13: =(V13-V12)/V12 -> -0.13406593 | AR13: =A13 -> 43900 | AS13: =B13*C13 -> 4051931.7 | AT13: =IF(AND($AS13 >= $BI$2, $C13 >= $BJ$2), ($C13 / $BK$2) * 100, "") | AU13: =U13 -> 43900 | AV13: =V13*W13 -> 22733376 | AW13: =IF(AND($AV13 >= $BM$2, $W13 >= $BN$2), ($W13 / $BO$2) * 100, "") | BD13: 45091 | BE13: 99707160 | BG13: 45338 | BH13: 22128497
A14: 43901 | B14: 480.427 | C14: 7572 | D14: =(B14-B13)/B13 -> 0.052759943 | U14: 43901 | V14: 31.175 | W14: 659850 | X14: =(V14-V13)/V13 -> 0.05499154 | AR14: =A14 -> 43901 | AS14: =B14*C14 -> 3637793.2 | AT14: =IF(AND($AS14 >= $BI$2, $C14 >= $BJ$2), ($C14 / $BK$2) * 100, "") | AU14: =U14 -> 43901 | AV14: =V14*W14 -> 20570824 | AW14: =IF(AND($AV14 >= $BM$2, $W14 >= $BN$2), ($W14 / $BO$2) * 100, "") | BD14: 45092 | BE14: 2.0683238e+08 | BG14: 45342 | BH14: 14416235
